Workbook

Sheet 📊 Dashboard Control
A1: PANEL DE CONTROL E INVENTARIOS - POLE DANCE ACADEMY
A3: ⚡ CONSULTA RÁPIDA DE PRODUCTO Y CONSECUTIVO
A4: Escribe el Código de Prenda: | C4: TM
A5: Descripción del Producto: | C5: =IFERROR(VLOOKUP(C4,#REF!, 3, FALSE()), "⚠️ Código no encontrado") -> ⚠️ Código no encontrado
A6: Talla: | C6: =IFERROR(VLOOKUP(C4,#REF!, 4, FALSE()), "-") -> -
A7: Precio de Venta Unitario: | C7: =IFERROR(VLOOKUP(C4,#REF!, 6, FALSE()), 0) -> 0
A8: Existencias Actuales (Stock): | C8: =IFERROR(VLOOKUP(C4,#REF!, 10, FALSE()), 0) -> 0
A9: Total Unidades Vendidas: | C9: =SUMIF('🛒 Ventas'!C:C, C4, '🛒 Ventas'!G:G) -> 0
A10: PRÓXIMO CONSECUTIVO DE VENTA: | C10: =IF(C4="","", C4 & (SUMIF('🛒 Ventas'!C:C, C4, '🛒 Ventas'!G:G) + 1)) -> TM1
A12: RESUMEN GENERAL ACADEMIA
A14: UNIDADES EN STOCK | C14: VALOR INVENTARIO ROPA | E14: VENTAS TOTALES ($) | G14: VALOR ACTIVOS FIJOS ($) | I14: GASTOS TOTALES ($) | K14: BALANCE NETO ($)
A15: =SUM(Marcancia!G:G)-SUM('🛒 Ventas'!G:G) -> 71 | C15: =IFERROR((SUM(Marcancia!J:J)/SUM(Marcancia!G:G))*A15,0) -> 2787150 | E15: =SUM('🛒 Ventas'!I2:I41) -> 0 | G15: =SUM('🏢 Activos Fijos'!H2:H47) -> 20857007 | I15: =SUM('💸 Gastos'!E2:E65) -> 14256280 | K15: =E15-I15 -> -14256280
A19: VENTAS POR TIPO DE PRENDA | E19: VENTAS POR MÉTODO DE PAGO
A21: Tipo Prenda | B21: Unidades Vendidas | C21: Total Recaudado ($) | E21: Método Pago | F21: N° Transacciones | G21: Total ($)
A22: Short (S) | B22: =SUMIF('🛒 Ventas'!C:C, "S*", '🛒 Ventas'!G:G) -> 0 | C22: =SUMIF('🛒 Ventas'!C:C, "S*", '🛒 Ventas'!I:I) -> 0 | E22: Nequi | F22: =COUNTIF('🛒 Ventas'!J:J, "Nequi") -> 1 | G22: =SUMIF('🛒 Ventas'!J:J, "Nequi", '🛒 Ventas'!I:I) -> 0
A23: Pantalón (P) | B23: =SUMIF('🛒 Ventas'!C:C, "P*", '🛒 Ventas'!G:G) -> 0 | C23: =SUMIF('🛒 Ventas'!C:C, "P*", '🛒 Ventas'!I:I) -> 0 | E23: Daviplata | F23: =COUNTIF('🛒 Ventas'!J:J, "Daviplata") -> 0 | G23: =SUMIF('🛒 Ventas'!J:J, "Daviplata", '🛒 Ventas'!I:I) -> 0
A24: Top/Sujetador (T) | B24: =SUMIF('🛒 Ventas'!C:C, "T*", '🛒 Ventas'!G:G) -> 0 | C24: =SUMIF('🛒 Ventas'!C:C, "T*", '🛒 Ventas'!I:I) -> 0 | E24: Efectivo | F24: =COUNTIF('🛒 Ventas'!J:J, "Efectivo") -> 0 | G24: =SUMIF('🛒 Ventas'!J:J, "Efectivo", '🛒 Ventas'!I:I) -> 0
A25: Body (B) | B25: =SUMIF('🛒 Ventas'!C:C, "B*", '🛒 Ventas'!G:G) -> 0 | C25: =SUMIF('🛒 Ventas'!C:C, "B*", '🛒 Ventas'!I:I) -> 0 | E25: Transferencia Bancaria | F25: =COUNTIF('🛒 Ventas'!J:J, "Transferencia Bancaria") -> 0 | G25: =SUMIF('🛒 Ventas'!J:J, "Transferencia Bancaria", '🛒 Ventas'!I:I) -> 0
A26: Accesorio (A) | B26: =SUMIF('🛒 Ventas'!C:C, "A*", '🛒 Ventas'!G:G) -> 0 | C26: =SUMIF('🛒 Ventas'!C:C, "A*", '🛒 Ventas'!I:I) -> 0 | E26: Tarjeta Débito/Crédito | F26: =COUNTIF('🛒 Ventas'!J:J, "Tarjeta Débito/Crédito") -> 0 | G26: =SUMIF('🛒 Ventas'!J:J, "Tarjeta Débito/Crédito", '🛒 Ventas'!I:I) -> 0
A27: TOTALES | B27: =SUM(B22:B26) -> 0 | C27: =SUM(C22:C26) -> 0 | E27: TOTALES | F27: =SUM(F22:F26) -> 1 | G27: =SUM(G22:G26) -> 0

Sheet 📈 Resumen Dinámico
A1: RESUMEN DINÁMICO
A2: Estas tablas se recalculan solas a partir de Gastos y Ventas. No las edites directamente.
A4: GASTOS POR CATEGORÍA | F4: GASTOS POR MÉTODO DE PAGO
A5: Categoría | B5: N° Registros | C5: Total ($) | F5: Método Pago | G5: N° Registros | H5: Total ($)
A6: Arriendo | B6: =COUNTIF('💸 Gastos'!C:C,"Arriendo") -> 2 | C6: =SUMIF('💸 Gastos'!C:C,"Arriendo",'💸 Gastos'!E:E) -> 3950000 | F6: Nequi | G6: =COUNTIF('💸 Gastos'!H:H,"Nequi") -> 0 | H6: =SUMIF('💸 Gastos'!H:H,"Nequi",'💸 Gastos'!E:E) -> 0
A7: Servicios Públicos | B7: =COUNTIF('💸 Gastos'!C:C,"Servicios Públicos") -> 1 | C7: =SUMIF('💸 Gastos'!C:C,"Servicios Públicos",'💸 Gastos'!E:E) -> 35850 | F7: Daviplata | G7: =COUNTIF('💸 Gastos'!H:H,"Daviplata") -> 0 | H7: =SUMIF('💸 Gastos'!H:H,"Daviplata",'💸 Gastos'!E:E) -> 0
A8: Nómina / Personal | B8: =COUNTIF('💸 Gastos'!C:C,"Nómina / Personal") -> 1 | C8: =SUMIF('💸 Gastos'!C:C,"Nómina / Personal",'💸 Gastos'!E:E) -> 906000 | F8: Efectivo | G8: =COUNTIF('💸 Gastos'!H:H,"Efectivo") -> 62 | H8: =SUMIF('💸 Gastos'!H:H,"Efectivo",'💸 Gastos'!E:E) -> 14256280
A9: Insumos y Aseo | B9: =COUNTIF('💸 Gastos'!C:C,"Insumos y Aseo") -> 8 | C9: =SUMIF('💸 Gastos'!C:C,"Insumos y Aseo",'💸 Gastos'!E:E) -> 398403 | F9: Transferencia Bancaria | G9: =COUNTIF('💸 Gastos'!H:H,"Transferencia Bancaria") -> 0 | H9: =SUMIF('💸 Gastos'!H:H,"Transferencia Bancaria",'💸 Gastos'!E:E) -> 0
A10: Mantenimiento Equipos | B10: =COUNTIF('💸 Gastos'!C:C,"Mantenimiento Equipos") -> 0 | C10: =SUMIF('💸 Gastos'!C:C,"Mantenimiento Equipos",'💸 Gastos'!E:E) -> 0 | F10: Tarjeta Débito/Crédito | G10: =COUNTIF('💸 Gastos'!H:H,"Tarjeta Débito/Crédito") -> 0 | H10: =SUMIF('💸 Gastos'!H:H,"Tarjeta Débito/Crédito",'💸 Gastos'!E:E) -> 0
A11: Marketing y Publicidad | B11: =COUNTIF('💸 Gastos'!C:C,"Marketing y Publicidad") -> 8 | C11: =SUMIF('💸 Gastos'!C:C,"Marketing y Publicidad",'💸 Gastos'!E:E) -> 554179 | F11: TOTAL | G11: =SUM(G6:G10) -> 62 | H11: =SUM(H6:H10) -> 14256280
A12: Software / Suscripciones | B12: =COUNTIF('💸 Gastos'!C:C,"Software / Suscripciones") -> 0 | C12: =SUMIF('💸 Gastos'!C:C,"Software / Suscripciones",'💸 Gastos'!E:E) -> 0
A13: Mantenimiento Local/Infraestructura | B13: =COUNTIF('💸 Gastos'!C:C,"Mantenimiento Local/Infraestructura") -> 2 | C13: =SUMIF('💸 Gastos'!C:C,"Mantenimiento Local/Infraestructura",'💸 Gastos'!E:E) -> 6364500
A14: Envíos/Transporte | B14: =COUNTIF('💸 Gastos'!C:C,"Envíos/Transporte") -> 1 | C14: =SUMIF('💸 Gastos'!C:C,"Envíos/Transporte",'💸 Gastos'!E:E) -> 195000
A15: Otros | B15: =COUNTIF('💸 Gastos'!C:C,"Otros") -> 0 | C15: =SUMIF('💸 Gastos'!C:C,"Otros",'💸 Gastos'!E:E) -> 0
A16: TOTAL | B16: =SUM(B6:B15) -> 23 | C16: =SUM(C6:C15) -> 12403932
A18: VENTAS POR COLOR
A19: Color | B19: Unidades Vendidas | C19: Total ($)
A20: Negro | B20: =SUMIF('🛒 Ventas'!F:F,"Negro",'🛒 Ventas'!G:G) -> 0 | C20: =SUMIF('🛒 Ventas'!F:F,"Negro",'🛒 Ventas'!I:I) -> 0
A21: Azul | B21: =SUMIF('🛒 Ventas'!F:F,"Azul",'🛒 Ventas'!G:G) -> 0 | C21: =SUMIF('🛒 Ventas'!F:F,"Azul",'🛒 Ventas'!I:I) -> 0
A22: Rojo | B22: =SUMIF('🛒 Ventas'!F:F,"Rojo",'🛒 Ventas'!G:G) -> 0 | C22: =SUMIF('🛒 Ventas'!F:F,"Rojo",'🛒 Ventas'!I:I) -> 0
A23: Verde | B23: =SUMIF('🛒 Ventas'!F:F,"Verde",'🛒 Ventas'!G:G) -> 0 | C23: =SUMIF('🛒 Ventas'!F:F,"Verde",'🛒 Ventas'!I:I) -> 0
A24: Amarillo | B24: =SUMIF('🛒 Ventas'!F:F,"Amarillo",'🛒 Ventas'!G:G) -> 0 | C24: =SUMIF('🛒 Ventas'!F:F,"Amarillo",'🛒 Ventas'!I:I) -> 0
A25: Blanco | B25: =SUMIF('🛒 Ventas'!F:F,"Blanco",'🛒 Ventas'!G:G) -> 0 | C25: =SUMIF('🛒 Ventas'!F:F,"Blanco",'🛒 Ventas'!I:I) -> 0
A26: TOTAL | B26: =SUM(B20:B25) -> 0 | C26: =SUM(C20:C25) -> 0

Sheet 🎓 Alumnas
A1: ID Alumna | B1: Nombre | C1: Cel | D1: Correo | E1: Dirección | F1: Fecha de nacimiento | G1: Edad | H1: N° de inscripciones (paquetes) | I1: N° de pagos registrados | J1: Total pagado ($) | K1: Primera fecha | L1: Última fecha | M1: Estado
A2: A-001 | B2: Ana Carolina Lopez Galvan | C2: 3229015452 | D2: anacaloga88@gmail.com | E2: carrera 79a#16f | F2: 32232 | G2: =IF(F2="","",DATEDIF(F2,TODAY(),"Y")) -> 38 | H2: =IF(B2="","",COUNTIFS('🤸 Ingresos Pole'!$C$2:$C$1000,B2,'🤸 Ingresos Pole'!$J$2:$J$1000,"Paquete")) -> 1 | I2: =IF(B2="","",COUNTIF('🤸 Ingresos Pole'!$C$2:$C$1000,B2)) -> 1 | J2: =IF(B2="","",SUMIF('🤸 Ingresos Pole'!$C$2:$C$1000,B2,'🤸 Ingresos Pole'!$N$2:$N$1000)) -> 200000 | K2: =IF(OR(B2="",I2=0),"",_xlfn.MINIFS('🤸 Ingresos Pole'!$B$2:$B$1000,'🤸 Ingresos Pole'!$C$2:$C$1000,B2)) -> 46264 | L2: =IF(OR(B2="",I2=0),"",_xlfn.MAXIFS('🤸 Ingresos Pole'!$B$2:$B$1000,'🤸 Ingresos Pole'!$C$2:$C$1000,B2)) -> 46264 | M2: =IF(OR(B2="",I2=0),"",IF(H2=0,"Sin paquete",IF(H2=1,"Nueva","Recurrente"))) -> Nueva
A3: A-002 | B3: Francya Damaris Arias Ospitia | C3: 3142183412 | D3: fraariaspi@hotmail.com | E3: Cra 73# 7f-07 | F3: 27887 | G3: =IF(F3="","",DATEDIF(F3,TODAY(),"Y")) -> 50 | H3: =IF(B3="","",COUNTIFS('🤸 Ingresos Pole'!$C$2:$C$1000,B3,'🤸 Ingresos Pole'!$J$2:$J$1000,"Paquete")) -> 1 | I3: =IF(B3="","",COUNTIF('🤸 Ingresos Pole'!$C$2:$C$1000,B3)) -> 1 | J3: =IF(B3="","",SUMIF('🤸 Ingresos Pole'!$C$2:$C$1000,B3,'🤸 Ingresos Pole'!$N$2:$N$1000)) -> 350000 | K3: =IF(OR(B3="",I3=0),"",_xlfn.MINIFS('🤸 Ingresos Pole'!$B$2:$B$1000,'🤸 Ingresos Pole'!$C$2:$C$1000,B3)) -> 46265 | L3: =IF(OR(B3="",I3=0),"",_xlfn.MAXIFS('🤸 Ingresos Pole'!$B$2:$B$1000,'🤸 Ingresos Pole'!$C$2:$C$1000,B3)) -> 46265 | M3: =IF(OR(B3="",I3=0),"",IF(H3=0,"Sin paquete",IF(H3=1,"Nueva","Recurrente"))) -> Nueva
A4: A-003 | B4: Diana Bermudez Cardona | C4: 3196364084 | D4: diana0.bermudez@gmail.com | E4: Cra 72k # 39a 96 sur | F4: 33374 | G4: =IF(F4="","",DATEDIF(F4,TODAY(),"Y")) -> 35 | H4: =IF(B4="","",COUNTIFS('🤸 Ingresos Pole'!$C$2:$C$1000,B4,'🤸 Ingresos Pole'!$J$2:$J$1000,"Paquete")) -> 2 | I4: =IF(B4="","",COUNTIF('🤸 Ingresos Pole'!$C$2:$C$1000,B4)) -> 2 | J4: =IF(B4="","",SUMIF('🤸 Ingresos Pole'!$C$2:$C$1000,B4,'🤸 Ingresos Pole'!$N$2:$N$1000)) -> 960000 | K4: =IF(OR(B4="",I4=0),"",_xlfn.MINIFS('🤸 Ingresos Pole'!$B$2:$B$1000,'🤸 Ingresos Pole'!$C$2:$C$1000,B4)) -> 46264 | L4: =IF(OR(B4="",I4=0),"",_xlfn.MAXIFS('🤸 Ingresos Pole'!$B$2:$B$1000,'🤸 Ingresos Pole'!$C$2:$C$1000,B4)) -> 46295 | M4: =IF(OR(B4="",I4=0),"",IF(H4=0,"Sin paquete",IF(H4=1,"Nueva","Recurrente"))) -> Recurrente
A5: A-004 | B5: Jessica Torres Olarte | C5: 3104775381 | D5: Jessicatorresolarte@gmail.com | E5: Calle 6b 80b 85 | F5: 31592 | G5: =IF(F5="","",DATEDIF(F5,TODAY(),"Y")) -> 40 | H5: =IF(B5="","",COUNTIFS('🤸 Ingresos Pole'!$C$2:$C$1000,B5,'🤸 Ingresos Pole'!$J$2:$J$1000,"Paquete")) -> 2 | I5: =IF(B5="","",COUNTIF('🤸 Ingresos Pole'!$C$2:$C$1000,B5)) -> 2 | J5: =IF(B5="","",SUMIF('🤸 Ingresos Pole'!$C$2:$C$1000,B5,'🤸 Ingresos Pole'!$N$2:$N$1000)) -> 0 | K5: =IF(OR(B5="",I5=0),"",_xlfn.MINIFS('🤸 Ingresos Pole'!$B$2:$B$1000,'🤸 Ingresos Pole'!$C$2:$C$1000,B5)) -> 46264 | L5: =IF(OR(B5="",I5=0),"",_xlfn.MAXIFS('🤸 Ingresos Pole'!$B$2:$B$1000,'🤸 Ingresos Pole'!$C$2:$C$1000,B5)) -> 46295 | M5: =IF(OR(B5="",I5=0),"",IF(H5=0,"Sin paquete",IF(H5=1,"Nueva","Recurrente"))) -> Recurrente
A6: A-005 | B6: Laura Camila Ramirez Galvis | G6: =IF(F6="","",DATEDIF(F6,TODAY(),"Y")) | H6: =IF(B6="","",COUNTIFS('🤸 Ingresos Pole'!$C$2:$C$1000,B6,'🤸 Ingresos Pole'!$J$2:$J$1000,"Paquete")) -> 1 | I6: =IF(B6="","",COUNTIF('🤸 Ingresos Pole'!$C$2:$C$1000,B6)) -> 1 | J6: =IF(B6="","",SUMIF('🤸 Ingresos Pole'!$C$2:$C$1000,B6,'🤸 Ingresos Pole'!$N$2:$N$1000)) -> 480000 | K6: =IF(OR(B6="",I6=0),"",_xlfn.MINIFS('🤸 Ingresos Pole'!$B$2:$B$1000,'🤸 Ingresos Pole'!$C$2:$C$1000,B6)) -> 46265 | L6: =IF(OR(B6="",I6=0),"",_xlfn.MAXIFS('🤸 Ingresos Pole'!$B$2:$B$1000,'🤸 Ingresos Pole'!$C$2:$C$1000,B6)) -> 46265 | M6: =IF(OR(B6="",I6=0),"",IF(H6=0,"Sin paquete",IF(H6=1,"Nueva","Recurrente"))) -> Nueva
A7: A-006 | B7: Juliana Bossa | C7: 3185937737 | G7: =IF(F7="","",DATEDIF(F7,TODAY(),"Y")) | H7: =IF(B7="","",COUNTIFS('🤸 Ingresos Pole'!$C$2:$C$1000,B7,'🤸 Ingresos Pole'!$J$2:$J$1000,"Paquete")) -> 0 | I7: =IF(B7="","",COUNTIF('🤸 Ingresos Pole'!$C$2:$C$1000,B7)) -> 2 | J7: =IF(B7="","",SUMIF('🤸 Ingresos Pole'!$C$2:$C$1000,B7,'🤸 Ingresos Pole'!$N$2:$N$1000)) -> 44000 | K7: =IF(OR(B7="",I7=0),"",_xlfn.MINIFS('🤸 Ingresos Pole'!$B$2:$B$1000,'🤸 Ingresos Pole'!$C$2:$C$1000,B7)) -> 46267 | L7: =IF(OR(B7="",I7=0),"",_xlfn.MAXIFS('🤸 Ingresos Pole'!$B$2:$B$1000,'🤸 Ingresos Pole'!$C$2:$C$1000,B7)) -> 46283 | M7: =IF(OR(B7="",I7=0),"",IF(H7=0,"Sin paquete",IF(H7=1,"Nueva","Recurrente"))) -> Sin paquete
A8: A-007 | B8: Laura Vanesa Guerra | G8: =IF(F8="","",DATEDIF(F8,TODAY(),"Y")) | H8: =IF(B8="","",COUNTIFS('🤸 Ingresos Pole'!$C$2:$C$1000,B8,'🤸 Ingresos Pole'!$J$2:$J$1000,"Paquete")) -> 2 | I8: =IF(B8="","",COUNTIF('🤸 Ingresos Pole'!$C$2:$C$1000,B8)) -> 2 | J8: =IF(B8="","",SUMIF('🤸 Ingresos Pole'!$C$2:$C$1000,B8,'🤸 Ingresos Pole'!$N$2:$N$1000)) -> 480000 | K8: =IF(OR(B8="",I8=0),"",_xlfn.MINIFS('🤸 Ingresos Pole'!$B$2:$B$1000,'🤸 Ingresos Pole'!$C$2:$C$1000,B8)) -> 46267 | L8: =IF(OR(B8="",I8=0),"",_xlfn.MAXIFS('🤸 Ingresos Pole'!$B$2:$B$1000,'🤸 Ingresos Pole'!$C$2:$C$1000,B8)) -> 46295 | M8: =IF(OR(B8="",I8=0),"",IF(H8=0,"Sin paquete",IF(H8=1,"Nueva","Recurrente"))) -> Recurrente
A9: A-008 | B9: Shirley Dayana Chavarro | C9: 3115269836 | G9: =IF(F9="","",DATEDIF(F9,TODAY(),"Y")) | H9: =IF(B9="","",COUNTIFS('🤸 Ingresos Pole'!$C$2:$C$1000,B9,'🤸 Ingresos Pole'!$J$2:$J$1000,"Paquete")) -> 2 | I9: =IF(B9="","",COUNTIF('🤸 Ingresos Pole'!$C$2:$C$1000,B9)) -> 2 | J9: =IF(B9="","",SUMIF('🤸 Ingresos Pole'!$C$2:$C$1000,B9,'🤸 Ingresos Pole'!$N$2:$N$1000)) -> 480000 | K9: =IF(OR(B9="",I9=0),"",_xlfn.MINIFS('🤸 Ingresos Pole'!$B$2:$B$1000,'🤸 Ingresos Pole'!$C$2:$C$1000,B9)) -> 46267 | L9: =IF(OR(B9="",I9=0),"",_xlfn.MAXIFS('🤸 Ingresos Pole'!$B$2:$B$1000,'🤸 Ingresos Pole'!$C$2:$C$1000,B9)) -> 46295 | M9: =IF(OR(B9="",I9=0),"",IF(H9=0,"Sin paquete",IF(H9=1,"Nueva","Recurrente"))) -> Recurrente
A10: A-009 | B10: Maria Paula Leon | G10: =IF(F10="","",DATEDIF(F10,TODAY(),"Y")) | H10: =IF(B10="","",COUNTIFS('🤸 Ingresos Pole'!$C$2:$C$1000,B10,'🤸 Ingresos Pole'!$J$2:$J$1000,"Paquete")) -> 1 | I10: =IF(B10="","",COUNTIF('🤸 Ingresos Pole'!$C$2:$C$1000,B10)) -> 1 | J10: =IF(B10="","",SUMIF('🤸 Ingresos Pole'!$C$2:$C$1000,B10,'🤸 Ingresos Pole'!$N$2:$N$1000)) -> 240000 | K10: =IF(OR(B10="",I10=0),"",_xlfn.MINIFS('🤸 Ingresos Pole'!$B$2:$B$1000,'🤸 Ingresos Pole'!$C$2:$C$1000,B10)) -> 46267 | L10: =IF(OR(B10="",I10=0),"",_xlfn.MAXIFS('🤸 Ingresos Pole'!$B$2:$B$1000,'🤸 Ingresos Pole'!$C$2:$C$1000,B10)) -> 46267 | M10: =IF(OR(B10="",I10=0),"",IF(H10=0,"Sin paquete",IF(H10=1,"Nueva","Recurrente"))) -> Nueva
A11: A-010 | B11: Ntalia Alejandra Luna | G11: =IF(F11="","",DATEDIF(F11,TODAY(),"Y")) | H11: =IF(B11="","",COUNTIFS('🤸 Ingresos Pole'!$C$2:$C$1000,B11,'🤸 Ingresos Pole'!$J$2:$J$1000,"Paquete")) -> 1 | I11: =IF(B11="","",COUNTIF('🤸 Ingresos Pole'!$C$2:$C$1000,B11)) -> 1 | J11: =IF(B11="","",SUMIF('🤸 Ingresos Pole'!$C$2:$C$1000,B11,'🤸 Ingresos Pole'!$N$2:$N$1000)) -> 240000 | K11: =IF(OR(B11="",I11=0),"",_xlfn.MINIFS('🤸 Ingresos Pole'!$B$2:$B$1000,'🤸 Ingresos Pole'!$C$2:$C$1000,B11)) -> 46272 | L11: =IF(OR(B11="",I11=0),"",_xlfn.MAXIFS('🤸 Ingresos Pole'!$B$2:$B$1000,'🤸 Ingresos Pole'!$C$2:$C$1000,B11)) -> 46272 | M11: =IF(OR(B11="",I11=0),"",IF(H11=0,"Sin paquete",IF(H11=1,"Nueva","Recurrente"))) -> Nueva
A12: A-011 | B12: Marcella Cuellar | G12: =IF(F12="","",DATEDIF(F12,TODAY(),"Y")) | H12: =IF(B12="","",COUNTIFS('🤸 Ingresos Pole'!$C$2:$C$1000,B12,'🤸 Ingresos Pole'!$J$2:$J$1000,"Paquete")) -> 1 | I12: =IF(B12="","",COUNTIF('🤸 Ingresos Pole'!$C$2:$C$1000,B12)) -> 1 | J12: =IF(B12="","",SUMIF('🤸 Ingresos Pole'!$C$2:$C$1000,B12,'🤸 Ingresos Pole'!$N$2:$N$1000)) -> 240000 | K12: =IF(OR(B12="",I12=0),"",_xlfn.MINIFS('🤸 Ingresos Pole'!$B$2:$B$1000,'🤸 Ingresos Pole'!$C$2:$C$1000,B12)) -> 46272 | L12: =IF(OR(B12="",I12=0),"",_xlfn.MAXIFS('🤸 Ingresos Pole'!$B$2:$B$1000,'🤸 Ingresos Pole'!$C$2:$C$1000,B12)) -> 46272 | M12: =IF(OR(B12="",I12=0),"",IF(H12=0,"Sin paquete",IF(H12=1,"Nueva","Recurrente"))) -> Nueva
A13: A-012 | B13: Danial Avila | G13: =IF(F13="","",DATEDIF(F13,TODAY(),"Y")) | H13: =IF(B13="","",COUNTIFS('🤸 Ingresos Pole'!$C$2:$C$1000,B13,'🤸 Ingresos Pole'!$J$2:$J$1000,"Paquete")) -> 0 | I13: =IF(B13="","",COUNTIF('🤸 Ingresos Pole'!$C$2:$C$1000,B13)) -> 2 | J13: =IF(B13="","",SUMIF('🤸 Ingresos Pole'!$C$2:$C$1000,B13,'🤸 Ingresos Pole'!$N$2:$N$1000)) -> 44000 | K13: =IF(OR(B13="",I13=0),"",_xlfn.MINIFS('🤸 Ingresos Pole'!$B$2:$B$1000,'🤸 Ingresos Pole'!$C$2:$C$1000,B13)) -> 46274 | L13: =IF(OR(B13="",I13=0),"",_xlfn.MAXIFS('🤸 Ingresos Pole'!$B$2:$B$1000,'🤸 Ingresos Pole'!$C$2:$C$1000,B13)) -> 46281 | M13: =IF(OR(B13="",I13=0),"",IF(H13=0,"Sin paquete",IF(H13=1,"Nueva","Recurrente"))) -> Sin paquete
A14: A-013 | B14: Karol Sierra | G14: =IF(F14="","",DATEDIF(F14,TODAY(),"Y")) | H14: =IF(B14="","",COUNTIFS('🤸 Ingresos Pole'!$C$2:$C$1000,B14,'🤸 Ingresos Pole'!$J$2:$J$1000,"Paquete")) -> 0 | I14: =IF(B14="","",COUNTIF('🤸 Ingresos Pole'!$C$2:$C$1000,B14)) -> 4 | J14: =IF(B14="","",SUMIF('🤸 Ingresos Pole'!$C$2:$C$1000,B14,'🤸 Ingresos Pole'!$N$2:$N$1000)) -> 132000 | K14: =IF(OR(B14="",I14=0),"",_xlfn.MINIFS('🤸 Ingresos Pole'!$B$2:$B$1000,'🤸 Ingresos Pole'!$C$2:$C$1000,B14)) -> 46274 | L14: =IF(OR(B14="",I14=0),"",_xlfn.MAXIFS('🤸 Ingresos Pole'!$B$2:$B$1000,'🤸 Ingresos Pole'!$C$2:$C$1000,B14)) -> 46295 | M14: =IF(OR(B14="",I14=0),"",IF(H14=0,"Sin paquete",IF(H14=1,"Nueva","Recurrente"))) -> Sin paquete
A15: A-014 | B15: Maira Alejandra Vergara | G15: =IF(F15="","",DATEDIF(F15,TODAY(),"Y")) | H15: =IF(B15="","",COUNTIFS('🤸 Ingresos Pole'!$C$2:$C$1000,B15,'🤸 Ingresos Pole'!$J$2:$J$1000,"Paquete")) -> 2 | I15: =IF(B15="","",COUNTIF('🤸 Ingresos Pole'!$C$2:$C$1000,B15)) -> 2 | J15: =IF(B15="","",SUMIF('🤸 Ingresos Pole'!$C$2:$C$1000,B15,'🤸 Ingresos Pole'!$N$2:$N$1000)) -> 590000 | K15: =IF(OR(B15="",I15=0),"",_xlfn.MINIFS('🤸 Ingresos Pole'!$B$2:$B$1000,'🤸 Ingresos Pole'!$C$2:$C$1000,B15)) -> 46276 | L15: =IF(OR(B15="",I15=0),"",_xlfn.MAXIFS('🤸 Ingresos Pole'!$B$2:$B$1000,'🤸 Ingresos Pole'!$C$2:$C$1000,B15)) -> 46295 | M15: =IF(OR(B15="",I15=0),"",IF(H15=0,"Sin paquete",IF(H15=1,"Nueva","Recurrente"))) -> Recurrente
A16: A-015 | B16: Jose Alberto Rojas Gonzalez | G16: =IF(F16="","",DATEDIF(F16,TODAY(),"Y")) | H16: =IF(B16="","",COUNTIFS('🤸 Ingresos Pole'!$C$2:$C$1000,B16,'🤸 Ingresos Pole'!$J$2:$J$1000,"Paquete")) -> 0 | I16: =IF(B16="","",COUNTIF('🤸 Ingresos Pole'!$C$2:$C$1000,B16)) -> 1 | J16: =IF(B16="","",SUMIF('🤸 Ingresos Pole'!$C$2:$C$1000,B16,'🤸 Ingresos Pole'!$N$2:$N$1000)) -> 44000 | K16: =IF(OR(B16="",I16=0),"",_xlfn.MINIFS('🤸 Ingresos Pole'!$B$2:$B$1000,'🤸 Ingresos Pole'!$C$2:$C$1000,B16)) -> 46280 | L16: =IF(OR(B16="",I16=0),"",_xlfn.MAXIFS('🤸 Ingresos Pole'!$B$2:$B$1000,'🤸 Ingresos Pole'!$C$2:$C$1000,B16)) -> 46280 | M16: =IF(OR(B16="",I16=0),"",IF(H16=0,"Sin paquete",IF(H16=1,"Nueva","Recurrente"))) -> Sin paquete
A17: A-016 | B17: Laura Sofia Hilarion | C17: 3204479014 | G17: =IF(F17="","",DATEDIF(F17,TODAY(),"Y")) | H17: =IF(B17="","",COUNTIFS('🤸 Ingresos Pole'!$C$2:$C$1000,B17,'🤸 Ingresos Pole'!$J$2:$J$1000,"Paquete")) -> 1 | I17: =IF(B17="","",COUNTIF('🤸 Ingresos Pole'!$C$2:$C$1000,B17)) -> 1 | J17: =IF(B17="","",SUMIF('🤸 Ingresos Pole'!$C$2:$C$1000,B17,'🤸 Ingresos Pole'!$N$2:$N$1000)) -> 480000 | K17: =IF(OR(B17="",I17=0),"",_xlfn.MINIFS('🤸 Ingresos Pole'!$B$2:$B$1000,'🤸 Ingresos Pole'!$C$2:$C$1000,B17)) -> 46281 | L17: =IF(OR(B17="",I17=0),"",_xlfn.MAXIFS('🤸 Ingresos Pole'!$B$2:$B$1000,'🤸 Ingresos Pole'!$C$2:$C$1000,B17)) -> 46281 | M17: =IF(OR(B17="",I17=0),"",IF(H17=0,"Sin paquete",IF(H17=1,"Nueva","Recurrente"))) -> Nueva
A18: A-017 | B18: Alejandra Ortega | C18: 3114401669 | G18: =IF(F18="","",DATEDIF(F18,TODAY(),"Y")) | H18: =IF(B18="","",COUNTIFS('🤸 Ingresos Pole'!$C$2:$C$1000,B18,'🤸 Ingresos Pole'!$J$2:$J$1000,"Paquete")) -> 1 | I18: =IF(B18="","",COUNTIF('🤸 Ingresos Pole'!$C$2:$C$1000,B18)) -> 1 | J18: =IF(B18="","",SUMIF('🤸 Ingresos Pole'!$C$2:$C$1000,B18,'🤸 Ingresos Pole'!$N$2:$N$1000)) -> 240000 | K18: =IF(OR(B18="",I18=0),"",_xlfn.MINIFS('🤸 Ingresos Pole'!$B$2:$B$1000,'🤸 Ingresos Pole'!$C$2:$C$1000,B18)) -> 46283 | L18: =IF(OR(B18="",I18=0),"",_xlfn.MAXIFS('🤸 Ingresos Pole'!$B$2:$B$1000,'🤸 Ingresos Pole'!$C$2:$C$1000,B18)) -> 46283 | M18: =IF(OR(B18="",I18=0),"",IF(H18=0,"Sin paquete",IF(H18=1,"Nueva","Recurrente"))) -> Nueva
A19: A-018 | B19: Mary Aurora Osorio Alvarez | C19: 3186650375 | G19: =IF(F19="","",DATEDIF(F19,TODAY(),"Y")) | H19: =IF(B19="","",COUNTIFS('🤸 Ingresos Pole'!$C$2:$C$1000,B19,'🤸 Ingresos Pole'!$J$2:$J$1000,"Paquete")) -> 1 | I19: =IF(B19="","",COUNTIF('🤸 Ingresos Pole'!$C$2:$C$1000,B19)) -> 2 | J19: =IF(B19="","",SUMIF('🤸 Ingresos Pole'!$C$2:$C$1000,B19,'🤸 Ingresos Pole'!$N$2:$N$1000)) -> 290000 | K19: =IF(OR(B19="",I19=0),"",_xlfn.MINIFS('🤸 Ingresos Pole'!$B$2:$B$1000,'🤸 Ingresos Pole'!$C$2:$C$1000,B19)) -> 46283 | L19: =IF(OR(B19="",I19=0),"",_xlfn.MAXIFS('🤸 Ingresos Pole'!$B$2:$B$1000,'🤸 Ingresos Pole'!$C$2:$C$1000,B19)) -> 46295 | M19: =IF(OR(B19="",I19=0),"",IF(H19=0,"Sin paquete",IF(H19=1,"Nueva","Recurrente"))) -> Nueva
A20: A-019 | B20: Elizabeth Lopez salamanca | C20: 3197067161 | G20: =IF(F20="","",DATEDIF(F20,TODAY(),"Y")) | H20: =IF(B20="","",COUNTIFS('🤸 Ingresos Pole'!$C$2:$C$1000,B20,'🤸 Ingresos Pole'!$J$2:$J$1000,"Paquete")) -> 0 | I20: =IF(B20="","",COUNTIF('🤸 Ingresos Pole'!$C$2:$C$1000,B20)) -> 1 | J20: =IF(B20="","",SUMIF('🤸 Ingresos Pole'!$C$2:$C$1000,B20,'🤸 Ingresos Pole'!$N$2:$N$1000)) -> 50000 | K20: =IF(OR(B20="",I20=0),"",_xlfn.MINIFS('🤸 Ingresos Pole'!$B$2:$B$1000,'🤸 Ingresos Pole'!$C$2:$C$1000,B20)) -> 46283 | L20: =IF(OR(B20="",I20=0),"",_xlfn.MAXIFS('🤸 Ingresos Pole'!$B$2:$B$1000,'🤸 Ingresos Pole'!$C$2:$C$1000,B20)) -> 46283 | M20: =IF(OR(B20="",I20=0),"",IF(H20=0,"Sin paquete",IF(H20=1,"Nueva","Recurrente"))) -> Sin paquete
A21: A-020 | B21: Paula Andrea Pinzon | G21: =IF(F21="","",DATEDIF(F21,TODAY(),"Y")) | H21: =IF(B21="","",COUNTIFS('🤸 Ingresos Pole'!$C$2:$C$1000,B21,'🤸 Ingresos Pole'!$J$2:$J$1000,"Paquete")) -> 1 | I21: =IF(B21="","",COUNTIF('🤸 Ingresos Pole'!$C$2:$C$1000,B21)) -> 2 | J21: =IF(B21="","",SUMIF('🤸 Ingresos Pole'!$C$2:$C$1000,B21,'🤸 Ingresos Pole'!$N$2:$N$1000)) -> 200000 | K21: =IF(OR(B21="",I21=0),"",_xlfn.MINIFS('🤸 Ingresos Pole'!$B$2:$B$1000,'🤸 Ingresos Pole'!$C$2:$C$1000,B21)) -> 46287 | L21: =IF(OR(B21="",I21=0),"",_xlfn.MAXIFS('🤸 Ingresos Pole'!$B$2:$B$1000,'🤸 Ingresos Pole'!$C$2:$C$1000,B21)) -> 46291 | M21: =IF(OR(B21="",I21=0),"",IF(H21=0,"Sin paquete",IF(H21=1,"Nueva","Recurrente"))) -> Nueva
A22: A-021 | B22: Marcela Garcia Sanabria | C22: 3123221477 | G22: =IF(F22="","",DATEDIF(F22,TODAY(),"Y")) | H22: =IF(B22="","",COUNTIFS('🤸 Ingresos Pole'!$C$2:$C$1000,B22,'🤸 Ingresos Pole'!$J$2:$J$1000,"Paquete")) -> 1 | I22: =IF(B22="","",COUNTIF('🤸 Ingresos Pole'!$C$2:$C$1000,B22)) -> 1 | J22: =IF(B22="","",SUMIF('🤸 Ingresos Pole'!$C$2:$C$1000,B22,'🤸 Ingresos Pole'!$N$2:$N$1000)) -> 350000 | K22: =IF(OR(B22="",I22=0),"",_xlfn.MINIFS('🤸 Ingresos Pole'!$B$2:$B$1000,'🤸 Ingresos Pole'!$C$2:$C$1000,B22)) -> 46291 | L22: =IF(OR(B22="",I22=0),"",_xlfn.MAXIFS('🤸 Ingresos Pole'!$B$2:$B$1000,'🤸 Ingresos Pole'!$C$2:$C$1000,B22)) -> 46291 | M22: =IF(OR(B22="",I22=0),"",IF(H22=0,"Sin paquete",IF(H22=1,"Nueva","Recurrente"))) -> Nueva
A23: A-022 | B23: Carolina Lopez | G23: =IF(F23="","",DATEDIF(F23,TODAY(),"Y")) | H23: =IF(B23="","",COUNTIFS('🤸 Ingresos Pole'!$C$2:$C$1000,B23,'🤸 Ingresos Pole'!$J$2:$J$1000,"Paquete")) -> 1 | I23: =IF(B23="","",COUNTIF('🤸 Ingresos Pole'!$C$2:$C$1000,B23)) -> 1 | J23: =IF(B23="","",SUMIF('🤸 Ingresos Pole'!$C$2:$C$1000,B23,'🤸 Ingresos Pole'!$N$2:$N$1000)) -> 240000 | K23: =IF(OR(B23="",I23=0),"",_xlfn.MINIFS('🤸 Ingresos Pole'!$B$2:$B$1000,'🤸 Ingresos Pole'!$C$2:$C$1000,B23)) -> 46293 | L23: =IF(OR(B23="",I23=0),"",_xlfn.MAXIFS('🤸 Ingresos Pole'!$B$2:$B$1000,'🤸 Ingresos Pole'!$C$2:$C$1000,B23)) -> 46293 | M23: =IF(OR(B23="",I23=0),"",IF(H23=0,"Sin paquete",IF(H23=1,"Nueva","Recurrente"))) -> Nueva
A24: A-023 | B24: Francya Dámaris Arias | G24: =IF(F24="","",DATEDIF(F24,TODAY(),"Y")) | H24: =IF(B24="","",COUNTIFS('🤸 Ingresos Pole'!$C$2:$C$1000,B24,'🤸 Ingresos Pole'!$J$2:$J$1000,"Paquete")) -> 1 | I24: =IF(B24="","",COUNTIF('🤸 Ingresos Pole'!$C$2:$C$1000,B24)) -> 1 | J24: =IF(B24="","",SUMIF('🤸 Ingresos Pole'!$C$2:$C$1000,B24,'🤸 Ingresos Pole'!$N$2:$N$1000)) -> 480000 | K24: =IF(OR(B24="",I24=0),"",_xlfn.MINIFS('🤸 Ingresos Pole'!$B$2:$B$1000,'🤸 Ingresos Pole'!$C$2:$C$1000,B24)) -> 46294 | L24: =IF(OR(B24="",I24=0),"",_xlfn.MAXIFS('🤸 Ingresos Pole'!$B$2:$B$1000,'🤸 Ingresos Pole'!$C$2:$C$1000,B24)) -> 46294 | M24: =IF(OR(B24="",I24=0),"",IF(H24=0,"Sin paquete",IF(H24=1,"Nueva","Recurrente"))) -> Nueva
A25: A-024 | B25: Karen Arias Ospitia | G25: =IF(F25="","",DATEDIF(F25,TODAY(),"Y")) | H25: =IF(B25="","",COUNTIFS('🤸 Ingresos Pole'!$C$2:$C$1000,B25,'🤸 Ingresos Pole'!$J$2:$J$1000,"Paquete")) -> 1 | I25: =IF(B25="","",COUNTIF('🤸 Ingresos Pole'!$C$2:$C$1000,B25)) -> 1 | J25: =IF(B25="","",SUMIF('🤸 Ingresos Pole'!$C$2:$C$1000,B25,'🤸 Ingresos Pole'!$N$2:$N$1000)) -> 0 | K25: =IF(OR(B25="",I25=0),"",_xlfn.MINIFS('🤸 Ingresos Pole'!$B$2:$B$1000,'🤸 Ingresos Pole'!$C$2:$C$1000,B25)) -> 46294 | L25: =IF(OR(B25="",I25=0),"",_xlfn.MAXIFS('🤸 Ingresos Pole'!$B$2:$B$1000,'🤸 Ingresos Pole'!$C$2:$C$1000,B25)) -> 46294 | M25: =IF(OR(B25="",I25=0),"",IF(H25=0,"Sin paquete",IF(H25=1,"Nueva","Recurrente"))) -> Nueva
A26: A-025 | B26: Yendi Alejandra Dugarte | G26: =IF(F26="","",DATEDIF(F26,TODAY(),"Y")) | H26: =IF(B26="","",COUNTIFS('🤸 Ingresos Pole'!$C$2:$C$1000,B26,'🤸 Ingresos Pole'!$J$2:$J$1000,"Paquete")) -> 1 | I26: =IF(B26="","",COUNTIF('🤸 Ingresos Pole'!$C$2:$C$1000,B26)) -> 1 | J26: =IF(B26="","",SUMIF('🤸 Ingresos Pole'!$C$2:$C$1000,B26,'🤸 Ingresos Pole'!$N$2:$N$1000)) -> 240000 | K26: =IF(OR(B26="",I26=0),"",_xlfn.MINIFS('🤸 Ingresos Pole'!$B$2:$B$1000,'🤸 Ingresos Pole'!$C$2:$C$1000,B26)) -> 46294 | L26: =IF(OR(B26="",I26=0),"",_xlfn.MAXIFS('🤸 Ingresos Pole'!$B$2:$B$1000,'🤸 Ingresos Pole'!$C$2:$C$1000,B26)) -> 46294 | M26: =IF(OR(B26="",I26=0),"",IF(H26=0,"Sin paquete",IF(H26=1,"Nueva","Recurrente"))) -> Nueva
A27: A-026 | B27: Martha Yasmin Aragón | G27: =IF(F27="","",DATEDIF(F27,TODAY(),"Y")) | H27: =IF(B27="","",COUNTIFS('🤸 Ingresos Pole'!$C$2:$C$1000,B27,'🤸 Ingresos Pole'!$J$2:$J$1000,"Paquete")) -> 1 | I27: =IF(B27="","",COUNTIF('🤸 Ingresos Pole'!$C$2:$C$1000,B27)) -> 2 | J27: =IF(B27="","",SUMIF('🤸 Ingresos Pole'!$C$2:$C$1000,B27,'🤸 Ingresos Pole'!$N$2:$N$1000)) -> 290000 | K27: =IF(OR(B27="",I27=0),"",_xlfn.MINIFS('🤸 Ingresos Pole'!$B$2:$B$1000,'🤸 Ingresos Pole'!$C$2:$C$1000,B27)) -> 46294 | L27: =IF(OR(B27="",I27=0),"",_xlfn.MAXIFS('🤸 Ingresos Pole'!$B$2:$B$1000,'🤸 Ingresos Pole'!$C$2:$C$1000,B27)) -> 46295 | M27: =IF(OR(B27="",I27=0),"",IF(H27=0,"Sin paquete",IF(H27=1,"Nueva","Recurrente"))) -> Nueva
A28: A-027 | B28: Melanie Jankey Ávila | G28: =IF(F28="","",DATEDIF(F28,TODAY(),"Y")) | H28: =IF(B28="","",COUNTIFS('🤸 Ingresos Pole'!$C$2:$C$1000,B28,'🤸 Ingresos Pole'!$J$2:$J$1000,"Paquete")) -> 1 | I28: =IF(B28="","",COUNTIF('🤸 Ingresos Pole'!$C$2:$C$1000,B28)) -> 1 | J28: =IF(B28="","",SUMIF('🤸 Ingresos Pole'!$C$2:$C$1000,B28,'🤸 Ingresos Pole'!$N$2:$N$1000)) -> 240000 | K28: =IF(OR(B28="",I28=0),"",_xlfn.MINIFS('🤸 Ingresos Pole'!$B$2:$B$1000,'🤸 Ingresos Pole'!$C$2:$C$1000,B28)) -> 46295 | L28: =IF(OR(B28="",I28=0),"",_xlfn.MAXIFS('🤸 Ingresos Pole'!$B$2:$B$1000,'🤸 Ingresos Pole'!$C$2:$C$1000,B28)) -> 46295 | M28: =IF(OR(B28="",I28=0),"",IF(H28=0,"Sin paquete",IF(H28=1,"Nueva","Recurrente"))) -> Nueva
A29: A-028 | G29: =IF(F29="","",DATEDIF(F29,TODAY(),"Y")) | H29: =IF(B29="","",COUNTIFS('🤸 Ingresos Pole'!$C$2:$C$1000,B29,'🤸 Ingresos Pole'!$J$2:$J$1000,"Paquete")) | I29: =IF(B29="","",COUNTIF('🤸 Ingresos Pole'!$C$2:$C$1000,B29)) | J29: =IF(B29="","",SUMIF('🤸 Ingresos Pole'!$C$2:$C$1000,B29,'🤸 Ingresos Pole'!$N$2:$N$1000)) | K29: =IF(OR(B29="",I29=0),"",_xlfn.MINIFS('🤸 Ingresos Pole'!$B$2:$B$1000,'🤸 Ingresos Pole'!$C$2:$C$1000,B29)) | L29: =IF(OR(B29="",I29=0),"",_xlfn.MAXIFS('🤸 Ingresos Pole'!$B$2:$B$1000,'🤸 Ingresos Pole'!$C$2:$C$1000,B29)) | M29: =IF(OR(B29="",I29=0),"",IF(H29=0,"Sin paquete",IF(H29=1,"Nueva","Recurrente")))
A30: A-029 | G30: =IF(F30="","",DATEDIF(F30,TODAY(),"Y")) | H30: =IF(B30="","",COUNTIFS('🤸 Ingresos Pole'!$C$2:$C$1000,B30,'🤸 Ingresos Pole'!$J$2:$J$1000,"Paquete")) | I30: =IF(B30="","",COUNTIF('🤸 Ingresos Pole'!$C$2:$C$1000,B30)) | J30: =IF(B30="","",SUMIF('🤸 Ingresos Pole'!$C$2:$C$1000,B30,'🤸 Ingresos Pole'!$N$2:$N$1000)) | K30: =IF(OR(B30="",I30=0),"",_xlfn.MINIFS('🤸 Ingresos Pole'!$B$2:$B$1000,'🤸 Ingresos Pole'!$C$2:$C$1000,B30)) | L30: =IF(OR(B30="",I30=0),"",_xlfn.MAXIFS('🤸 Ingresos Pole'!$B$2:$B$1000,'🤸 Ingresos Pole'!$C$2:$C$1000,B30)) | M30: =IF(OR(B30="",I30=0),"",IF(H30=0,"Sin paquete",IF(H30=1,"Nueva","Recurrente")))
A31: A-030 | G31: =IF(F31="","",DATEDIF(F31,TODAY(),"Y")) | H31: =IF(B31="","",COUNTIFS('🤸 Ingresos Pole'!$C$2:$C$1000,B31,'🤸 Ingresos Pole'!$J$2:$J$1000,"Paquete")) | I31: =IF(B31="","",COUNTIF('🤸 Ingresos Pole'!$C$2:$C$1000,B31)) | J31: =IF(B31="","",SUMIF('🤸 Ingresos Pole'!$C$2:$C$1000,B31,'🤸 Ingresos Pole'!$N$2:$N$1000)) | K31: =IF(OR(B31="",I31=0),"",_xlfn.MINIFS('🤸 Ingresos Pole'!$B$2:$B$1000,'🤸 Ingresos Pole'!$C$2:$C$1000,B31)) | L31: =IF(OR(B31="",I31=0),"",_xlfn.MAXIFS('🤸 Ingresos Pole'!$B$2:$B$1000,'🤸 Ingresos Pole'!$C$2:$C$1000,B31)) | M31: =IF(OR(B31="",I31=0),"",IF(H31=0,"Sin paquete",IF(H31=1,"Nueva","Recurrente")))
A32: A-031 | G32: =IF(F32="","",DATEDIF(F32,TODAY(),"Y")) | H32: =IF(B32="","",COUNTIFS('🤸 Ingresos Pole'!$C$2:$C$1000,B32,'🤸 Ingresos Pole'!$J$2:$J$1000,"Paquete")) | I32: =IF(B32="","",COUNTIF('🤸 Ingresos Pole'!$C$2:$C$1000,B32)) | J32: =IF(B32="","",SUMIF('🤸 Ingresos Pole'!$C$2:$C$1000,B32,'🤸 Ingresos Pole'!$N$2:$N$1000)) | K32: =IF(OR(B32="",I32=0),"",_xlfn.MINIFS('🤸 Ingresos Pole'!$B$2:$B$1000,'🤸 Ingresos Pole'!$C$2:$C$1000,B32)) | L32: =IF(OR(B32="",I32=0),"",_xlfn.MAXIFS('🤸 Ingresos Pole'!$B$2:$B$1000,'🤸 Ingresos Pole'!$C$2:$C$1000,B32)) | M32: =IF(OR(B32="",I32=0),"",IF(H32=0,"Sin paquete",IF(H32=1,"Nueva","Recurrente")))
A33: A-032 | G33: =IF(F33="","",DATEDIF(F33,TODAY(),"Y")) | H33: =IF(B33="","",COUNTIFS('🤸 Ingresos Pole'!$C$2:$C$1000,B33,'🤸 Ingresos Pole'!$J$2:$J$1000,"Paquete")) | I33: =IF(B33="","",COUNTIF('🤸 Ingresos Pole'!$C$2:$C$1000,B33)) | J33: =IF(B33="","",SUMIF('🤸 Ingresos Pole'!$C$2:$C$1000,B33,'🤸 Ingresos Pole'!$N$2:$N$1000)) | K33: =IF(OR(B33="",I33=0),"",_xlfn.MINIFS('🤸 Ingresos Pole'!$B$2:$B$1000,'🤸 Ingresos Pole'!$C$2:$C$1000,B33)) | L33: =IF(OR(B33="",I33=0),"",_xlfn.MAXIFS('🤸 Ingresos Pole'!$B$2:$B$1000,'🤸 Ingresos Pole'!$C$2:$C$1000,B33)) | M33: =IF(OR(B33="",I33=0),"",IF(H33=0,"Sin paquete",IF(H33=1,"Nueva","Recurrente")))
A34: A-033 | G34: =IF(F34="","",DATEDIF(F34,TODAY(),"Y")) | H34: =IF(B34="","",COUNTIFS('🤸 Ingresos Pole'!$C$2:$C$1000,B34,'🤸 Ingresos Pole'!$J$2:$J$1000,"Paquete")) | I34: =IF(B34="","",COUNTIF('🤸 Ingresos Pole'!$C$2:$C$1000,B34)) | J34: =IF(B34="","",SUMIF('🤸 Ingresos Pole'!$C$2:$C$1000,B34,'🤸 Ingresos Pole'!$N$2:$N$1000)) | K34: =IF(OR(B34="",I34=0),"",_xlfn.MINIFS('🤸 Ingresos Pole'!$B$2:$B$1000,'🤸 Ingresos Pole'!$C$2:$C$1000,B34)) | L34: =IF(OR(B34="",I34=0),"",_xlfn.MAXIFS('🤸 Ingresos Pole'!$B$2:$B$1000,'🤸 Ingresos Pole'!$C$2:$C$1000,B34)) | M34: =IF(OR(B34="",I34=0),"",IF(H34=0,"Sin paquete",IF(H34=1,"Nueva","Recurrente")))
A35: A-034 | G35: =IF(F35="","",DATEDIF(F35,TODAY(),"Y")) | H35: =IF(B35="","",COUNTIFS('🤸 Ingresos Pole'!$C$2:$C$1000,B35,'🤸 Ingresos Pole'!$J$2:$J$1000,"Paquete")) | I35: =IF(B35="","",COUNTIF('🤸 Ingresos Pole'!$C$2:$C$1000,B35)) | J35: =IF(B35="","",SUMIF('🤸 Ingresos Pole'!$C$2:$C$1000,B35,'🤸 Ingresos Pole'!$N$2:$N$1000)) | K35: =IF(OR(B35="",I35=0),"",_xlfn.MINIFS('🤸 Ingresos Pole'!$B$2:$B$1000,'🤸 Ingresos Pole'!$C$2:$C$1000,B35)) | L35: =IF(OR(B35="",I35=0),"",_xlfn.MAXIFS('🤸 Ingresos Pole'!$B$2:$B$1000,'🤸 Ingresos Pole'!$C$2:$C$1000,B35)) | M35: =IF(OR(B35="",I35=0),"",IF(H35=0,"Sin paquete",IF(H35=1,"Nueva","Recurrente")))
A36: A-035 | G36: =IF(F36="","",DATEDIF(F36,TODAY(),"Y")) | H36: =IF(B36="","",COUNTIFS('🤸 Ingresos Pole'!$C$2:$C$1000,B36,'🤸 Ingresos Pole'!$J$2:$J$1000,"Paquete")) | I36: =IF(B36="","",COUNTIF('🤸 Ingresos Pole'!$C$2:$C$1000,B36)) | J36: =IF(B36="","",SUMIF('🤸 Ingresos Pole'!$C$2:$C$1000,B36,'🤸 Ingresos Pole'!$N$2:$N$1000)) | K36: =IF(OR(B36="",I36=0),"",_xlfn.MINIFS('🤸 Ingresos Pole'!$B$2:$B$1000,'🤸 Ingresos Pole'!$C$2:$C$1000,B36)) | L36: =IF(OR(B36="",I36=0),"",_xlfn.MAXIFS('🤸 Ingresos Pole'!$B$2:$B$1000,'🤸 Ingresos Pole'!$C$2:$C$1000,B36)) | M36: =IF(OR(B36="",I36=0),"",IF(H36=0,"Sin paquete",IF(H36=1,"Nueva","Recurrente")))
A37: A-036 | G37: =IF(F37="","",DATEDIF(F37,TODAY(),"Y")) | H37: =IF(B37="","",COUNTIFS('🤸 Ingresos Pole'!$C$2:$C$1000,B37,'🤸 Ingresos Pole'!$J$2:$J$1000,"Paquete")) | I37: =IF(B37="","",COUNTIF('🤸 Ingresos Pole'!$C$2:$C$1000,B37)) | J37: =IF(B37="","",SUMIF('🤸 Ingresos Pole'!$C$2:$C$1000,B37,'🤸 Ingresos Pole'!$N$2:$N$1000)) | K37: =IF(OR(B37="",I37=0),"",_xlfn.MINIFS('🤸 Ingresos Pole'!$B$2:$B$1000,'🤸 Ingresos Pole'!$C$2:$C$1000,B37)) | L37: =IF(OR(B37="",I37=0),"",_xlfn.MAXIFS('🤸 Ingresos Pole'!$B$2:$B$1000,'🤸 Ingresos Pole'!$C$2:$C$1000,B37)) | M37: =IF(OR(B37="",I37=0),"",IF(H37=0,"Sin paquete",IF(H37=1,"Nueva","Recurrente")))
A38: A-037 | G38: =IF(F38="","",DATEDIF(F38,TODAY(),"Y")) | H38: =IF(B38="","",COUNTIFS('🤸 Ingresos Pole'!$C$2:$C$1000,B38,'🤸 Ingresos Pole'!$J$2:$J$1000,"Paquete")) | I38: =IF(B38="","",COUNTIF('🤸 Ingresos Pole'!$C$2:$C$1000,B38)) | J38: =IF(B38="","",SUMIF('🤸 Ingresos Pole'!$C$2:$C$1000,B38,'🤸 Ingresos Pole'!$N$2:$N$1000)) | K38: =IF(OR(B38="",I38=0),"",_xlfn.MINIFS('🤸 Ingresos Pole'!$B$2:$B$1000,'🤸 Ingresos Pole'!$C$2:$C$1000,B38)) | L38: =IF(OR(B38="",I38=0),"",_xlfn.MAXIFS('🤸 Ingresos Pole'!$B$2:$B$1000,'🤸 Ingresos Pole'!$C$2:$C$1000,B38)) | M38: =IF(OR(B38="",I38=0),"",IF(H38=0,"Sin paquete",IF(H38=1,"Nueva","Recurrente")))
A39: A-038 | G39: =IF(F39="","",DATEDIF(F39,TODAY(),"Y")) | H39: =IF(B39="","",COUNTIFS('🤸 Ingresos Pole'!$C$2:$C$1000,B39,'🤸 Ingresos Pole'!$J$2:$J$1000,"Paquete")) | I39: =IF(B39="","",COUNTIF('🤸 Ingresos Pole'!$C$2:$C$1000,B39)) | J39: =IF(B39="","",SUMIF('🤸 Ingresos Pole'!$C$2:$C$1000,B39,'🤸 Ingresos Pole'!$N$2:$N$1000)) | K39: =IF(OR(B39="",I39=0),"",_xlfn.MINIFS('🤸 Ingresos Pole'!$B$2:$B$1000,'🤸 Ingresos Pole'!$C$2:$C$1000,B39)) | L39: =IF(OR(B39="",I39=0),"",_xlfn.MAXIFS('🤸 Ingresos Pole'!$B$2:$B$1000,'🤸 Ingresos Pole'!$C$2:$C$1000,B39)) | M39: =IF(OR(B39="",I39=0),"",IF(H39=0,"Sin paquete",IF(H39=1,"Nueva","Recurrente")))
A40: A-039 | G40: =IF(F40="","",DATEDIF(F40,TODAY(),"Y")) | H40: =IF(B40="","",COUNTIFS('🤸 Ingresos Pole'!$C$2:$C$1000,B40,'🤸 Ingresos Pole'!$J$2:$J$1000,"Paquete")) | I40: =IF(B40="","",COUNTIF('🤸 Ingresos Pole'!$C$2:$C$1000,B40)) | J40: =IF(B40="","",SUMIF('🤸 Ingresos Pole'!$C$2:$C$1000,B40,'🤸 Ingresos Pole'!$N$2:$N$1000)) | K40: =IF(OR(B40="",I40=0),"",_xlfn.MINIFS('🤸 Ingresos Pole'!$B$2:$B$1000,'🤸 Ingresos Pole'!$C$2:$C$1000,B40)) | L40: =IF(OR(B40="",I40=0),"",_xlfn.MAXIFS('🤸 Ingresos Pole'!$B$2:$B$1000,'🤸 Ingresos Pole'!$C$2:$C$1000,B40)) | M40: =IF(OR(B40="",I40=0),"",IF(H40=0,"Sin paquete",IF(H40=1,"Nueva","Recurrente")))
...

Sheet 🤸 Ingresos Pole
A1: ID Ingreso | B1: Fecha | C1: Alumna | D1: Cel | E1: Correo | F1: Dirección | G1: Fecha de nacimiento | H1: Edad | I1: Concepto | J1: Tipo | K1: Descripción | L1: Cantidad | M1: Valor Unitario ($) | N1: Total ($) | O1: Porcentaje que paga | P1: Método de Pago | Q1: Registrado Por | R1: ¿Alumna nueva? | S1: N° de inscripción | T1: Notas
A2: I-001 | B2: 46264 | C2: Ana Carolina Lopez Galvan | D2: =IF($C2="","",IFERROR(IF(INDEX('🎓 Alumnas'!$C$2:$C$1000,MATCH($C2,'🎓 Alumnas'!$B$2:$B$1000,0))="","",INDEX('🎓 Alumnas'!$C$2:$C$1000,MATCH($C2,'🎓 Alumnas'!$B$2:$B$1000,0))),"")) -> 3229015452 | E2: =IF($C2="","",IFERROR(IF(INDEX('🎓 Alumnas'!$D$2:$D$1000,MATCH($C2,'🎓 Alumnas'!$B$2:$B$1000,0))="","",INDEX('🎓 Alumnas'!$D$2:$D$1000,MATCH($C2,'🎓 Alumnas'!$B$2:$B$1000,0))),"")) -> anacaloga88@gmail.com | F2: =IF($C2="","",IFERROR(IF(INDEX('🎓 Alumnas'!$E$2:$E$1000,MATCH($C2,'🎓 Alumnas'!$B$2:$B$1000,0))="","",INDEX('🎓 Alumnas'!$E$2:$E$1000,MATCH($C2,'🎓 Alumnas'!$B$2:$B$1000,0))),"")) -> carrera 79a#16f | G2: =IF($C2="","",IFERROR(IF(INDEX('🎓 Alumnas'!$F$2:$F$1000,MATCH($C2,'🎓 Alumnas'!$B$2:$B$1000,0))="","",INDEX('🎓 Alumnas'!$F$2:$F$1000,MATCH($C2,'🎓 Alumnas'!$B$2:$B$1000,0))),"")) -> 32232 | H2: =IF(G2="","",DATEDIF(G2,TODAY(),"Y")) -> 38 | I2: 4 clases: Sport Fitness Challenge $200.000 | J2: =IF(I2="","",IF(LEFT(I2,6)="1 Pole","Alquiler",IF(LEFT(I2,7)="1 Clase","Clase suelta","Paquete"))) -> Paquete | L2: 1 | M2: 200000 | N2: =IF(M2="","",L2*M2) -> 200000 | O2: 1 | P2: Transferencia Bancaria | Q2: Carolina | R2: =IF(C2="","",IF(COUNTIF($C$2:C2,C2)=1,"Nueva","Recurrente")) -> Nueva | S2: =IF(OR(C2="",J2<>"Paquete"),"",COUNTIFS($C$2:C2,C2,$J$2:J2,"Paquete")) -> 1
A3: I-002 | B3: 46265 | C3: Francya Damaris Arias Ospitia | D3: =IF($C3="","",IFERROR(IF(INDEX('🎓 Alumnas'!$C$2:$C$1000,MATCH($C3,'🎓 Alumnas'!$B$2:$B$1000,0))="","",INDEX('🎓 Alumnas'!$C$2:$C$1000,MATCH($C3,'🎓 Alumnas'!$B$2:$B$1000,0))),"")) -> 3142183412 | E3: =IF($C3="","",IFERROR(IF(INDEX('🎓 Alumnas'!$D$2:$D$1000,MATCH($C3,'🎓 Alumnas'!$B$2:$B$1000,0))="","",INDEX('🎓 Alumnas'!$D$2:$D$1000,MATCH($C3,'🎓 Alumnas'!$B$2:$B$1000,0))),"")) -> fraariaspi@hotmail.com | F3: =IF($C3="","",IFERROR(IF(INDEX('🎓 Alumnas'!$E$2:$E$1000,MATCH($C3,'🎓 Alumnas'!$B$2:$B$1000,0))="","",INDEX('🎓 Alumnas'!$E$2:$E$1000,MATCH($C3,'🎓 Alumnas'!$B$2:$B$1000,0))),"")) -> Cra 73# 7f-07 | G3: =IF($C3="","",IFERROR(IF(INDEX('🎓 Alumnas'!$F$2:$F$1000,MATCH($C3,'🎓 Alumnas'!$B$2:$B$1000,0))="","",INDEX('🎓 Alumnas'!$F$2:$F$1000,MATCH($C3,'🎓 Alumnas'!$B$2:$B$1000,0))),"")) -> 27887 | H3: =IF(G3="","",DATEDIF(G3,TODAY(),"Y")) -> 50 | I3: 9 clases: Sport Power Team $350.000 | J3: =IF(I3="","",IF(LEFT(I3,6)="1 Pole","Alquiler",IF(LEFT(I3,7)="1 Clase","Clase suelta","Paquete"))) -> Paquete | L3: 1 | M3: 350000 | N3: =IF(M3="","",L3*M3) -> 350000 | O3: 1 | P3: Efectivo | Q3: Jose | R3: =IF(C3="","",IF(COUNTIF($C$2:C3,C3)=1,"Nueva","Recurrente")) -> Nueva | S3: =IF(OR(C3="",J3<>"Paquete"),"",COUNTIFS($C$2:C3,C3,$J$2:J3,"Paquete")) -> 1
A4: I-003 | B4: 46264 | C4: Diana Bermudez Cardona | D4: =IF($C4="","",IFERROR(IF(INDEX('🎓 Alumnas'!$C$2:$C$1000,MATCH($C4,'🎓 Alumnas'!$B$2:$B$1000,0))="","",INDEX('🎓 Alumnas'!$C$2:$C$1000,MATCH($C4,'🎓 Alumnas'!$B$2:$B$1000,0))),"")) -> 3196364084 | E4: =IF($C4="","",IFERROR(IF(INDEX('🎓 Alumnas'!$D$2:$D$1000,MATCH($C4,'🎓 Alumnas'!$B$2:$B$1000,0))="","",INDEX('🎓 Alumnas'!$D$2:$D$1000,MATCH($C4,'🎓 Alumnas'!$B$2:$B$1000,0))),"")) -> diana0.bermudez@gmail.com | F4: =IF($C4="","",IFERROR(IF(INDEX('🎓 Alumnas'!$E$2:$E$1000,MATCH($C4,'🎓 Alumnas'!$B$2:$B$1000,0))="","",INDEX('🎓 Alumnas'!$E$2:$E$1000,MATCH($C4,'🎓 Alumnas'!$B$2:$B$1000,0))),"")) -> Cra 72k # 39a 96 sur | G4: =IF($C4="","",IFERROR(IF(INDEX('🎓 Alumnas'!$F$2:$F$1000,MATCH($C4,'🎓 Alumnas'!$B$2:$B$1000,0))="","",INDEX('🎓 Alumnas'!$F$2:$F$1000,MATCH($C4,'🎓 Alumnas'!$B$2:$B$1000,0))),"")) -> 33374 | H4: =IF(G4="","",DATEDIF(G4,TODAY(),"Y")) -> 35 | I4: 16 clases : Sport Elite club $480.000 | J4: =IF(I4="","",IF(LEFT(I4,6)="1 Pole","Alquiler",IF(LEFT(I4,7)="1 Clase","Clase suelta","Paquete"))) -> Paquete | K4: Promo 2x1 | L4: 1 | M4: 480000 | N4: =IF(M4="","",L4*M4) -> 480000 | O4: 1 | P4: Transferencia Bancaria | Q4: Carolina | R4: =IF(C4="","",IF(COUNTIF($C$2:C4,C4)=1,"Nueva","Recurrente")) -> Nueva | S4: =IF(OR(C4="",J4<>"Paquete"),"",COUNTIFS($C$2:C4,C4,$J$2:J4,"Paquete")) -> 1
A5: I-004 | B5: 46264 | C5: Jessica Torres Olarte | D5: =IF($C5="","",IFERROR(IF(INDEX('🎓 Alumnas'!$C$2:$C$1000,MATCH($C5,'🎓 Alumnas'!$B$2:$B$1000,0))="","",INDEX('🎓 Alumnas'!$C$2:$C$1000,MATCH($C5,'🎓 Alumnas'!$B$2:$B$1000,0))),"")) -> 3104775381 | E5: =IF($C5="","",IFERROR(IF(INDEX('🎓 Alumnas'!$D$2:$D$1000,MATCH($C5,'🎓 Alumnas'!$B$2:$B$1000,0))="","",INDEX('🎓 Alumnas'!$D$2:$D$1000,MATCH($C5,'🎓 Alumnas'!$B$2:$B$1000,0))),"")) -> Jessicatorresolarte@gmail.com | F5: =IF($C5="","",IFERROR(IF(INDEX('🎓 Alumnas'!$E$2:$E$1000,MATCH($C5,'🎓 Alumnas'!$B$2:$B$1000,0))="","",INDEX('🎓 Alumnas'!$E$2:$E$1000,MATCH($C5,'🎓 Alumnas'!$B$2:$B$1000,0))),"")) -> Calle 6b 80b 85 | G5: =IF($C5="","",IFERROR(IF(INDEX('🎓 Alumnas'!$F$2:$F$1000,MATCH($C5,'🎓 Alumnas'!$B$2:$B$1000,0))="","",INDEX('🎓 Alumnas'!$F$2:$F$1000,MATCH($C5,'🎓 Alumnas'!$B$2:$B$1000,0))),"")) -> 31592 | H5: =IF(G5="","",DATEDIF(G5,TODAY(),"Y")) -> 40 | I5: 16 clases : Sport Elite club $480.000 | J5: =IF(I5="","",IF(LEFT(I5,6)="1 Pole","Alquiler",IF(LEFT(I5,7)="1 Clase","Clase suelta","Paquete"))) -> Paquete | K5: Promo 2x1 | L5: 1 | M5: 0 | N5: =IF(M5="","",L5*M5) -> 0 | O5: 0 | R5: =IF(C5="","",IF(COUNTIF($C$2:C5,C5)=1,"Nueva","Recurrente")) -> Nueva | S5: =IF(OR(C5="",J5<>"Paquete"),"",COUNTIFS($C$2:C5,C5,$J$2:J5,"Paquete")) -> 1
A6: I-005 | B6: 46265 | C6: Laura Camila Ramirez Galvis | D6: =IF($C6="","",IFERROR(IF(INDEX('🎓 Alumnas'!$C$2:$C$1000,MATCH($C6,'🎓 Alumnas'!$B$2:$B$1000,0))="","",INDEX('🎓 Alumnas'!$C$2:$C$1000,MATCH($C6,'🎓 Alumnas'!$B$2:$B$1000,0))),"")) | E6: =IF($C6="","",IFERROR(IF(INDEX('🎓 Alumnas'!$D$2:$D$1000,MATCH($C6,'🎓 Alumnas'!$B$2:$B$1000,0))="","",INDEX('🎓 Alumnas'!$D$2:$D$1000,MATCH($C6,'🎓 Alumnas'!$B$2:$B$1000,0))),"")) | F6: =IF($C6="","",IFERROR(IF(INDEX('🎓 Alumnas'!$E$2:$E$1000,MATCH($C6,'🎓 Alumnas'!$B$2:$B$1000,0))="","",INDEX('🎓 Alumnas'!$E$2:$E$1000,MATCH($C6,'🎓 Alumnas'!$B$2:$B$1000,0))),"")) | G6: =IF($C6="","",IFERROR(IF(INDEX('🎓 Alumnas'!$F$2:$F$1000,MATCH($C6,'🎓 Alumnas'!$B$2:$B$1000,0))="","",INDEX('🎓 Alumnas'!$F$2:$F$1000,MATCH($C6,'🎓 Alumnas'!$B$2:$B$1000,0))),"")) | H6: =IF(G6="","",DATEDIF(G6,TODAY(),"Y")) | I6: 16 clases : Sport Elite club $480.000 | J6: =IF(I6="","",IF(LEFT(I6,6)="1 Pole","Alquiler",IF(LEFT(I6,7)="1 Clase","Clase suelta","Paquete"))) -> Paquete | K6: Promo 2x1 | L6: 1 | M6: 480000 | N6: =IF(M6="","",L6*M6) -> 480000 | O6: 1 | P6: Transferencia Bancaria | R6: =IF(C6="","",IF(COUNTIF($C$2:C6,C6)=1,"Nueva","Recurrente")) -> Nueva | S6: =IF(OR(C6="",J6<>"Paquete"),"",COUNTIFS($C$2:C6,C6,$J$2:J6,"Paquete")) -> 1
A7: I-006 | B7: 46267 | C7: Juliana Bossa | D7: =IF($C7="","",IFERROR(IF(INDEX('🎓 Alumnas'!$C$2:$C$1000,MATCH($C7,'🎓 Alumnas'!$B$2:$B$1000,0))="","",INDEX('🎓 Alumnas'!$C$2:$C$1000,MATCH($C7,'🎓 Alumnas'!$B$2:$B$1000,0))),"")) -> 3185937737 | E7: =IF($C7="","",IFERROR(IF(INDEX('🎓 Alumnas'!$D$2:$D$1000,MATCH($C7,'🎓 Alumnas'!$B$2:$B$1000,0))="","",INDEX('🎓 Alumnas'!$D$2:$D$1000,MATCH($C7,'🎓 Alumnas'!$B$2:$B$1000,0))),"")) | F7: =IF($C7="","",IFERROR(IF(INDEX('🎓 Alumnas'!$E$2:$E$1000,MATCH($C7,'🎓 Alumnas'!$B$2:$B$1000,0))="","",INDEX('🎓 Alumnas'!$E$2:$E$1000,MATCH($C7,'🎓 Alumnas'!$B$2:$B$1000,0))),"")) | G7: =IF($C7="","",IFERROR(IF(INDEX('🎓 Alumnas'!$F$2:$F$1000,MATCH($C7,'🎓 Alumnas'!$B$2:$B$1000,0))="","",INDEX('🎓 Alumnas'!$F$2:$F$1000,MATCH($C7,'🎓 Alumnas'!$B$2:$B$1000,0))),"")) | H7: =IF(G7="","",DATEDIF(G7,TODAY(),"Y")) | I7: 1 Pole: Alquiler $22000 | J7: =IF(I7="","",IF(LEFT(I7,6)="1 Pole","Alquiler",IF(LEFT(I7,7)="1 Clase","Clase suelta","Paquete"))) -> Alquiler | L7: 1 | M7: 22000 | N7: =IF(M7="","",L7*M7) -> 22000 | O7: 1 | P7: Nequi | R7: =IF(C7="","",IF(COUNTIF($C$2:C7,C7)=1,"Nueva","Recurrente")) -> Nueva | S7: =IF(OR(C7="",J7<>"Paquete"),"",COUNTIFS($C$2:C7,C7,$J$2:J7,"Paquete"))
A8: I-007 | B8: 46267 | C8: Laura Vanesa Guerra | D8: =IF($C8="","",IFERROR(IF(INDEX('🎓 Alumnas'!$C$2:$C$1000,MATCH($C8,'🎓 Alumnas'!$B$2:$B$1000,0))="","",INDEX('🎓 Alumnas'!$C$2:$C$1000,MATCH($C8,'🎓 Alumnas'!$B$2:$B$1000,0))),"")) | E8: =IF($C8="","",IFERROR(IF(INDEX('🎓 Alumnas'!$D$2:$D$1000,MATCH($C8,'🎓 Alumnas'!$B$2:$B$1000,0))="","",INDEX('🎓 Alumnas'!$D$2:$D$1000,MATCH($C8,'🎓 Alumnas'!$B$2:$B$1000,0))),"")) | F8: =IF($C8="","",IFERROR(IF(INDEX('🎓 Alumnas'!$E$2:$E$1000,MATCH($C8,'🎓 Alumnas'!$B$2:$B$1000,0))="","",INDEX('🎓 Alumnas'!$E$2:$E$1000,MATCH($C8,'🎓 Alumnas'!$B$2:$B$1000,0))),"")) | G8: =IF($C8="","",IFERROR(IF(INDEX('🎓 Alumnas'!$F$2:$F$1000,MATCH($C8,'🎓 Alumnas'!$B$2:$B$1000,0))="","",INDEX('🎓 Alumnas'!$F$2:$F$1000,MATCH($C8,'🎓 Alumnas'!$B$2:$B$1000,0))),"")) | H8: =IF(G8="","",DATEDIF(G8,TODAY(),"Y")) | I8: 16 clases : Sport Elite club $480.000 | J8: =IF(I8="","",IF(LEFT(I8,6)="1 Pole","Alquiler",IF(LEFT(I8,7)="1 Clase","Clase suelta","Paquete"))) -> Paquete | K8: Promo 2x1 | L8: 1 | M8: 240000 | N8: =IF(M8="","",L8*M8) -> 240000 | O8: 0.5 | P8: Transferencia Bancaria | R8: =IF(C8="","",IF(COUNTIF($C$2:C8,C8)=1,"Nueva","Recurrente")) -> Nueva | S8: =IF(OR(C8="",J8<>"Paquete"),"",COUNTIFS($C$2:C8,C8,$J$2:J8,"Paquete")) -> 1
A9: I-008 | B9: 46267 | C9: Shirley Dayana Chavarro | D9: =IF($C9="","",IFERROR(IF(INDEX('🎓 Alumnas'!$C$2:$C$1000,MATCH($C9,'🎓 Alumnas'!$B$2:$B$1000,0))="","",INDEX('🎓 Alumnas'!$C$2:$C$1000,MATCH($C9,'🎓 Alumnas'!$B$2:$B$1000,0))),"")) -> 3115269836 | E9: =IF($C9="","",IFERROR(IF(INDEX('🎓 Alumnas'!$D$2:$D$1000,MATCH($C9,'🎓 Alumnas'!$B$2:$B$1000,0))="","",INDEX('🎓 Alumnas'!$D$2:$D$1000,MATCH($C9,'🎓 Alumnas'!$B$2:$B$1000,0))),"")) | F9: =IF($C9="","",IFERROR(IF(INDEX('🎓 Alumnas'!$E$2:$E$1000,MATCH($C9,'🎓 Alumnas'!$B$2:$B$1000,0))="","",INDEX('🎓 Alumnas'!$E$2:$E$1000,MATCH($C9,'🎓 Alumnas'!$B$2:$B$1000,0))),"")) | G9: =IF($C9="","",IFERROR(IF(INDEX('🎓 Alumnas'!$F$2:$F$1000,MATCH($C9,'🎓 Alumnas'!$B$2:$B$1000,0))="","",INDEX('🎓 Alumnas'!$F$2:$F$1000,MATCH($C9,'🎓 Alumnas'!$B$2:$B$1000,0))),"")) | H9: =IF(G9="","",DATEDIF(G9,TODAY(),"Y")) | I9: 16 clases : Sport Elite club $480.000 | J9: =IF(I9="","",IF(LEFT(I9,6)="1 Pole","Alquiler",IF(LEFT(I9,7)="1 Clase","Clase suelta","Paquete"))) -> Paquete | K9: Promo 2x1 | L9: 1 | M9: 240000 | N9: =IF(M9="","",L9*M9) -> 240000 | O9: 0.5 | P9: Nequi | R9: =IF(C9="","",IF(COUNTIF($C$2:C9,C9)=1,"Nueva","Recurrente")) -> Nueva | S9: =IF(OR(C9="",J9<>"Paquete"),"",COUNTIFS($C$2:C9,C9,$J$2:J9,"Paquete")) -> 1
A10: I-009 | B10: 46267 | C10: Maria Paula Leon | D10: =IF($C10="","",IFERROR(IF(INDEX('🎓 Alumnas'!$C$2:$C$1000,MATCH($C10,'🎓 Alumnas'!$B$2:$B$1000,0))="","",INDEX('🎓 Alumnas'!$C$2:$C$1000,MATCH($C10,'🎓 Alumnas'!$B$2:$B$1000,0))),"")) | E10: =IF($C10="","",IFERROR(IF(INDEX('🎓 Alumnas'!$D$2:$D$1000,MATCH($C10,'🎓 Alumnas'!$B$2:$B$1000,0))="","",INDEX('🎓 Alumnas'!$D$2:$D$1000,MATCH($C10,'🎓 Alumnas'!$B$2:$B$1000,0))),"")) | F10: =IF($C10="","",IFERROR(IF(INDEX('🎓 Alumnas'!$E$2:$E$1000,MATCH($C10,'🎓 Alumnas'!$B$2:$B$1000,0))="","",INDEX('🎓 Alumnas'!$E$2:$E$1000,MATCH($C10,'🎓 Alumnas'!$B$2:$B$1000,0))),"")) | G10: =IF($C10="","",IFERROR(IF(INDEX('🎓 Alumnas'!$F$2:$F$1000,MATCH($C10,'🎓 Alumnas'!$B$2:$B$1000,0))="","",INDEX('🎓 Alumnas'!$F$2:$F$1000,MATCH($C10,'🎓 Alumnas'!$B$2:$B$1000,0))),"")) | H10: =IF(G10="","",DATEDIF(G10,TODAY(),"Y")) | I10: 16 clases : Sport Elite club $480.000 | J10: =IF(I10="","",IF(LEFT(I10,6)="1 Pole","Alquiler",IF(LEFT(I10,7)="1 Clase","Clase suelta","Paquete"))) -> Paquete | K10: Promo 2x1 | L10: 1 | M10: 240000 | N10: =IF(M10="","",L10*M10) -> 240000 | O10: 0.5 | P10: Transferencia Bancaria | R10: =IF(C10="","",IF(COUNTIF($C$2:C10,C10)=1,"Nueva","Recurrente")) -> Nueva | S10: =IF(OR(C10="",J10<>"Paquete"),"",COUNTIFS($C$2:C10,C10,$J$2:J10,"Paquete")) -> 1
A11: I-010 | B11: 46272 | C11: Ntalia Alejandra Luna | D11: =IF($C11="","",IFERROR(IF(INDEX('🎓 Alumnas'!$C$2:$C$1000,MATCH($C11,'🎓 Alumnas'!$B$2:$B$1000,0))="","",INDEX('🎓 Alumnas'!$C$2:$C$1000,MATCH($C11,'🎓 Alumnas'!$B$2:$B$1000,0))),"")) | E11: =IF($C11="","",IFERROR(IF(INDEX('🎓 Alumnas'!$D$2:$D$1000,MATCH($C11,'🎓 Alumnas'!$B$2:$B$1000,0))="","",INDEX('🎓 Alumnas'!$D$2:$D$1000,MATCH($C11,'🎓 Alumnas'!$B$2:$B$1000,0))),"")) | F11: =IF($C11="","",IFERROR(IF(INDEX('🎓 Alumnas'!$E$2:$E$1000,MATCH($C11,'🎓 Alumnas'!$B$2:$B$1000,0))="","",INDEX('🎓 Alumnas'!$E$2:$E$1000,MATCH($C11,'🎓 Alumnas'!$B$2:$B$1000,0))),"")) | G11: =IF($C11="","",IFERROR(IF(INDEX('🎓 Alumnas'!$F$2:$F$1000,MATCH($C11,'🎓 Alumnas'!$B$2:$B$1000,0))="","",INDEX('🎓 Alumnas'!$F$2:$F$1000,MATCH($C11,'🎓 Alumnas'!$B$2:$B$1000,0))),"")) | H11: =IF(G11="","",DATEDIF(G11,TODAY(),"Y")) | I11: 16 clases : Sport Elite club $480.000 | J11: =IF(I11="","",IF(LEFT(I11,6)="1 Pole","Alquiler",IF(LEFT(I11,7)="1 Clase","Clase suelta","Paquete"))) -> Paquete | K11: Promo 2x1 | L11: 1 | M11: 240000 | N11: =IF(M11="","",L11*M11) -> 240000 | O11: 0.5 | P11: Transferencia Bancaria | R11: =IF(C11="","",IF(COUNTIF($C$2:C11,C11)=1,"Nueva","Recurrente")) -> Nueva | S11: =IF(OR(C11="",J11<>"Paquete"),"",COUNTIFS($C$2:C11,C11,$J$2:J11,"Paquete")) -> 1
A12: I-011 | B12: 46272 | C12: Marcella Cuellar | D12: =IF($C12="","",IFERROR(IF(INDEX('🎓 Alumnas'!$C$2:$C$1000,MATCH($C12,'🎓 Alumnas'!$B$2:$B$1000,0))="","",INDEX('🎓 Alumnas'!$C$2:$C$1000,MATCH($C12,'🎓 Alumnas'!$B$2:$B$1000,0))),"")) | E12: =IF($C12="","",IFERROR(IF(INDEX('🎓 Alumnas'!$D$2:$D$1000,MATCH($C12,'🎓 Alumnas'!$B$2:$B$1000,0))="","",INDEX('🎓 Alumnas'!$D$2:$D$1000,MATCH($C12,'🎓 Alumnas'!$B$2:$B$1000,0))),"")) | F12: =IF($C12="","",IFERROR(IF(INDEX('🎓 Alumnas'!$E$2:$E$1000,MATCH($C12,'🎓 Alumnas'!$B$2:$B$1000,0))="","",INDEX('🎓 Alumnas'!$E$2:$E$1000,MATCH($C12,'🎓 Alumnas'!$B$2:$B$1000,0))),"")) | G12: =IF($C12="","",IFERROR(IF(INDEX('🎓 Alumnas'!$F$2:$F$1000,MATCH($C12,'🎓 Alumnas'!$B$2:$B$1000,0))="","",INDEX('🎓 Alumnas'!$F$2:$F$1000,MATCH($C12,'🎓 Alumnas'!$B$2:$B$1000,0))),"")) | H12: =IF(G12="","",DATEDIF(G12,TODAY(),"Y")) | I12: 16 clases : Sport Elite club $480.000 | J12: =IF(I12="","",IF(LEFT(I12,6)="1 Pole","Alquiler",IF(LEFT(I12,7)="1 Clase","Clase suelta","Paquete"))) -> Paquete | K12: Promo 2x1 | L12: 1 | M12: 240000 | N12: =IF(M12="","",L12*M12) -> 240000 | O12: 0.5 | P12: Transferencia Bancaria | R12: =IF(C12="","",IF(COUNTIF($C$2:C12,C12)=1,"Nueva","Recurrente")) -> Nueva | S12: =IF(OR(C12="",J12<>"Paquete"),"",COUNTIFS($C$2:C12,C12,$J$2:J12,"Paquete")) -> 1
A13: I-012 | B13: 46274 | C13: Danial Avila | D13: =IF($C13="","",IFERROR(IF(INDEX('🎓 Alumnas'!$C$2:$C$1000,MATCH($C13,'🎓 Alumnas'!$B$2:$B$1000,0))="","",INDEX('🎓 Alumnas'!$C$2:$C$1000,MATCH($C13,'🎓 Alumnas'!$B$2:$B$1000,0))),"")) | E13: =IF($C13="","",IFERROR(IF(INDEX('🎓 Alumnas'!$D$2:$D$1000,MATCH($C13,'🎓 Alumnas'!$B$2:$B$1000,0))="","",INDEX('🎓 Alumnas'!$D$2:$D$1000,MATCH($C13,'🎓 Alumnas'!$B$2:$B$1000,0))),"")) | F13: =IF($C13="","",IFERROR(IF(INDEX('🎓 Alumnas'!$E$2:$E$1000,MATCH($C13,'🎓 Alumnas'!$B$2:$B$1000,0))="","",INDEX('🎓 Alumnas'!$E$2:$E$1000,MATCH($C13,'🎓 Alumnas'!$B$2:$B$1000,0))),"")) | G13: =IF($C13="","",IFERROR(IF(INDEX('🎓 Alumnas'!$F$2:$F$1000,MATCH($C13,'🎓 Alumnas'!$B$2:$B$1000,0))="","",INDEX('🎓 Alumnas'!$F$2:$F$1000,MATCH($C13,'🎓 Alumnas'!$B$2:$B$1000,0))),"")) | H13: =IF(G13="","",DATEDIF(G13,TODAY(),"Y")) | I13: 1 Pole: Alquiler $22000 | J13: =IF(I13="","",IF(LEFT(I13,6)="1 Pole","Alquiler",IF(LEFT(I13,7)="1 Clase","Clase suelta","Paquete"))) -> Alquiler | L13: 1 | M13: 22000 | N13: =IF(M13="","",L13*M13) -> 22000 | O13: 1 | P13: Transferencia Bancaria | R13: =IF(C13="","",IF(COUNTIF($C$2:C13,C13)=1,"Nueva","Recurrente")) -> Nueva | S13: =IF(OR(C13="",J13<>"Paquete"),"",COUNTIFS($C$2:C13,C13,$J$2:J13,"Paquete"))
A14: I-013 | B14: 46274 | C14: Karol Sierra | D14: =IF($C14="","",IFERROR(IF(INDEX('🎓 Alumnas'!$C$2:$C$1000,MATCH($C14,'🎓 Alumnas'!$B$2:$B$1000,0))="","",INDEX('🎓 Alumnas'!$C$2:$C$1000,MATCH($C14,'🎓 Alumnas'!$B$2:$B$1000,0))),"")) | E14: =IF($C14="","",IFERROR(IF(INDEX('🎓 Alumnas'!$D$2:$D$1000,MATCH($C14,'🎓 Alumnas'!$B$2:$B$1000,0))="","",INDEX('🎓 Alumnas'!$D$2:$D$1000,MATCH($C14,'🎓 Alumnas'!$B$2:$B$1000,0))),"")) | F14: =IF($C14="","",IFERROR(IF(INDEX('🎓 Alumnas'!$E$2:$E$1000,MATCH($C14,'🎓 Alumnas'!$B$2:$B$1000,0))="","",INDEX('🎓 Alumnas'!$E$2:$E$1000,MATCH($C14,'🎓 Alumnas'!$B$2:$B$1000,0))),"")) | G14: =IF($C14="","",IFERROR(IF(INDEX('🎓 Alumnas'!$F$2:$F$1000,MATCH($C14,'🎓 Alumnas'!$B$2:$B$1000,0))="","",INDEX('🎓 Alumnas'!$F$2:$F$1000,MATCH($C14,'🎓 Alumnas'!$B$2:$B$1000,0))),"")) | H14: =IF(G14="","",DATEDIF(G14,TODAY(),"Y")) | I14: 1 Pole: Alquiler $22000 | J14: =IF(I14="","",IF(LEFT(I14,6)="1 Pole","Alquiler",IF(LEFT(I14,7)="1 Clase","Clase suelta","Paquete"))) -> Alquiler | L14: 1 | M14: 22000 | N14: =IF(M14="","",L14*M14) -> 22000 | O14: 1 | P14: Transferencia Bancaria | R14: =IF(C14="","",IF(COUNTIF($C$2:C14,C14)=1,"Nueva","Recurrente")) -> Nueva | S14: =IF(OR(C14="",J14<>"Paquete"),"",COUNTIFS($C$2:C14,C14,$J$2:J14,"Paquete"))
A15: I-015 | B15: 46276 | C15: Maira Alejandra Vergara | D15: =IF($C15="","",IFERROR(IF(INDEX('🎓 Alumnas'!$C$2:$C$1000,MATCH($C15,'🎓 Alumnas'!$B$2:$B$1000,0))="","",INDEX('🎓 Alumnas'!$C$2:$C$1000,MATCH($C15,'🎓 Alumnas'!$B$2:$B$1000,0))),"")) | E15: =IF($C15="","",IFERROR(IF(INDEX('🎓 Alumnas'!$D$2:$D$1000,MATCH($C15,'🎓 Alumnas'!$B$2:$B$1000,0))="","",INDEX('🎓 Alumnas'!$D$2:$D$1000,MATCH($C15,'🎓 Alumnas'!$B$2:$B$1000,0))),"")) | F15: =IF($C15="","",IFERROR(IF(INDEX('🎓 Alumnas'!$E$2:$E$1000,MATCH($C15,'🎓 Alumnas'!$B$2:$B$1000,0))="","",INDEX('🎓 Alumnas'!$E$2:$E$1000,MATCH($C15,'🎓 Alumnas'!$B$2:$B$1000,0))),"")) | G15: =IF($C15="","",IFERROR(IF(INDEX('🎓 Alumnas'!$F$2:$F$1000,MATCH($C15,'🎓 Alumnas'!$B$2:$B$1000,0))="","",INDEX('🎓 Alumnas'!$F$2:$F$1000,MATCH($C15,'🎓 Alumnas'!$B$2:$B$1000,0))),"")) | H15: =IF(G15="","",DATEDIF(G15,TODAY(),"Y")) | I15: 9 clases: Sport Power Team $350.000 | J15: =IF(I15="","",IF(LEFT(I15,6)="1 Pole","Alquiler",IF(LEFT(I15,7)="1 Clase","Clase suelta","Paquete"))) -> Paquete | L15: 1 | M15: 350000 | N15: =IF(M15="","",L15*M15) -> 350000 | O15: 1 | P15: Transferencia Bancaria | R15: =IF(C15="","",IF(COUNTIF($C$2:C15,C15)=1,"Nueva","Recurrente")) -> Nueva | S15: =IF(OR(C15="",J15<>"Paquete"),"",COUNTIFS($C$2:C15,C15,$J$2:J15,"Paquete")) -> 1
A16: I-016 | B16: 46280 | C16: Jose Alberto Rojas Gonzalez | D16: =IF($C16="","",IFERROR(IF(INDEX('🎓 Alumnas'!$C$2:$C$1000,MATCH($C16,'🎓 Alumnas'!$B$2:$B$1000,0))="","",INDEX('🎓 Alumnas'!$C$2:$C$1000,MATCH($C16,'🎓 Alumnas'!$B$2:$B$1000,0))),"")) | E16: =IF($C16="","",IFERROR(IF(INDEX('🎓 Alumnas'!$D$2:$D$1000,MATCH($C16,'🎓 Alumnas'!$B$2:$B$1000,0))="","",INDEX('🎓 Alumnas'!$D$2:$D$1000,MATCH($C16,'🎓 Alumnas'!$B$2:$B$1000,0))),"")) | F16: =IF($C16="","",IFERROR(IF(INDEX('🎓 Alumnas'!$E$2:$E$1000,MATCH($C16,'🎓 Alumnas'!$B$2:$B$1000,0))="","",INDEX('🎓 Alumnas'!$E$2:$E$1000,MATCH($C16,'🎓 Alumnas'!$B$2:$B$1000,0))),"")) | G16: =IF($C16="","",IFERROR(IF(INDEX('🎓 Alumnas'!$F$2:$F$1000,MATCH($C16,'🎓 Alumnas'!$B$2:$B$1000,0))="","",INDEX('🎓 Alumnas'!$F$2:$F$1000,MATCH($C16,'🎓 Alumnas'!$B$2:$B$1000,0))),"")) | H16: =IF(G16="","",DATEDIF(G16,TODAY(),"Y")) | I16: 1 Pole: Alquiler $22000 | J16: =IF(I16="","",IF(LEFT(I16,6)="1 Pole","Alquiler",IF(LEFT(I16,7)="1 Clase","Clase suelta","Paquete"))) -> Alquiler | L16: 2 | M16: 22000 | N16: =IF(M16="","",L16*M16) -> 44000 | O16: 1 | P16: Transferencia Bancaria | R16: =IF(C16="","",IF(COUNTIF($C$2:C16,C16)=1,"Nueva","Recurrente")) -> Nueva | S16: =IF(OR(C16="",J16<>"Paquete"),"",COUNTIFS($C$2:C16,C16,$J$2:J16,"Paquete"))
A17: I-017 | B17: 46281 | C17: Danial Avila | D17: =IF($C17="","",IFERROR(IF(INDEX('🎓 Alumnas'!$C$2:$C$1000,MATCH($C17,'🎓 Alumnas'!$B$2:$B$1000,0))="","",INDEX('🎓 Alumnas'!$C$2:$C$1000,MATCH($C17,'🎓 Alumnas'!$B$2:$B$1000,0))),"")) | E17: =IF($C17="","",IFERROR(IF(INDEX('🎓 Alumnas'!$D$2:$D$1000,MATCH($C17,'🎓 Alumnas'!$B$2:$B$1000,0))="","",INDEX('🎓 Alumnas'!$D$2:$D$1000,MATCH($C17,'🎓 Alumnas'!$B$2:$B$1000,0))),"")) | F17: =IF($C17="","",IFERROR(IF(INDEX('🎓 Alumnas'!$E$2:$E$1000,MATCH($C17,'🎓 Alumnas'!$B$2:$B$1000,0))="","",INDEX('🎓 Alumnas'!$E$2:$E$1000,MATCH($C17,'🎓 Alumnas'!$B$2:$B$1000,0))),"")) | G17: =IF($C17="","",IFERROR(IF(INDEX('🎓 Alumnas'!$F$2:$F$1000,MATCH($C17,'🎓 Alumnas'!$B$2:$B$1000,0))="","",INDEX('🎓 Alumnas'!$F$2:$F$1000,MATCH($C17,'🎓 Alumnas'!$B$2:$B$1000,0))),"")) | H17: =IF(G17="","",DATEDIF(G17,TODAY(),"Y")) | I17: 1 Pole: Alquiler $22000 | J17: =IF(I17="","",IF(LEFT(I17,6)="1 Pole","Alquiler",IF(LEFT(I17,7)="1 Clase","Clase suelta","Paquete"))) -> Alquiler | L17: 1 | M17: 22000 | N17: =IF(M17="","",L17*M17) -> 22000 | O17: 1 | P17: Transferencia Bancaria | R17: =IF(C17="","",IF(COUNTIF($C$2:C17,C17)=1,"Nueva","Recurrente")) -> Recurrente | S17: =IF(OR(C17="",J17<>"Paquete"),"",COUNTIFS($C$2:C17,C17,$J$2:J17,"Paquete"))
A18: I-018 | B18: 46281 | C18: Laura Sofia Hilarion | D18: =IF($C18="","",IFERROR(IF(INDEX('🎓 Alumnas'!$C$2:$C$1000,MATCH($C18,'🎓 Alumnas'!$B$2:$B$1000,0))="","",INDEX('🎓 Alumnas'!$C$2:$C$1000,MATCH($C18,'🎓 Alumnas'!$B$2:$B$1000,0))),"")) -> 3204479014 | E18: =IF($C18="","",IFERROR(IF(INDEX('🎓 Alumnas'!$D$2:$D$1000,MATCH($C18,'🎓 Alumnas'!$B$2:$B$1000,0))="","",INDEX('🎓 Alumnas'!$D$2:$D$1000,MATCH($C18,'🎓 Alumnas'!$B$2:$B$1000,0))),"")) | F18: =IF($C18="","",IFERROR(IF(INDEX('🎓 Alumnas'!$E$2:$E$1000,MATCH($C18,'🎓 Alumnas'!$B$2:$B$1000,0))="","",INDEX('🎓 Alumnas'!$E$2:$E$1000,MATCH($C18,'🎓 Alumnas'!$B$2:$B$1000,0))),"")) | G18: =IF($C18="","",IFERROR(IF(INDEX('🎓 Alumnas'!$F$2:$F$1000,MATCH($C18,'🎓 Alumnas'!$B$2:$B$1000,0))="","",INDEX('🎓 Alumnas'!$F$2:$F$1000,MATCH($C18,'🎓 Alumnas'!$B$2:$B$1000,0))),"")) | H18: =IF(G18="","",DATEDIF(G18,TODAY(),"Y")) | I18: 16 clases : Sport Elite club $480.000 | J18: =IF(I18="","",IF(LEFT(I18,6)="1 Pole","Alquiler",IF(LEFT(I18,7)="1 Clase","Clase suelta","Paquete"))) -> Paquete | L18: 1 | M18: 480000 | N18: =IF(M18="","",L18*M18) -> 480000 | O18: 1 | P18: Nequi | R18: =IF(C18="","",IF(COUNTIF($C$2:C18,C18)=1,"Nueva","Recurrente")) -> Nueva | S18: =IF(OR(C18="",J18<>"Paquete"),"",COUNTIFS($C$2:C18,C18,$J$2:J18,"Paquete")) -> 1
A19: I-019 | B19: 46283 | C19: Alejandra Ortega | D19: =IF($C19="","",IFERROR(IF(INDEX('🎓 Alumnas'!$C$2:$C$1000,MATCH($C19,'🎓 Alumnas'!$B$2:$B$1000,0))="","",INDEX('🎓 Alumnas'!$C$2:$C$1000,MATCH($C19,'🎓 Alumnas'!$B$2:$B$1000,0))),"")) -> 3114401669 | E19: =IF($C19="","",IFERROR(IF(INDEX('🎓 Alumnas'!$D$2:$D$1000,MATCH($C19,'🎓 Alumnas'!$B$2:$B$1000,0))="","",INDEX('🎓 Alumnas'!$D$2:$D$1000,MATCH($C19,'🎓 Alumnas'!$B$2:$B$1000,0))),"")) | F19: =IF($C19="","",IFERROR(IF(INDEX('🎓 Alumnas'!$E$2:$E$1000,MATCH($C19,'🎓 Alumnas'!$B$2:$B$1000,0))="","",INDEX('🎓 Alumnas'!$E$2:$E$1000,MATCH($C19,'🎓 Alumnas'!$B$2:$B$1000,0))),"")) | G19: =IF($C19="","",IFERROR(IF(INDEX('🎓 Alumnas'!$F$2:$F$1000,MATCH($C19,'🎓 Alumnas'!$B$2:$B$1000,0))="","",INDEX('🎓 Alumnas'!$F$2:$F$1000,MATCH($C19,'🎓 Alumnas'!$B$2:$B$1000,0))),"")) | H19: =IF(G19="","",DATEDIF(G19,TODAY(),"Y")) | I19: 16 clases : Sport Elite club $480.000 | J19: =IF(I19="","",IF(LEFT(I19,6)="1 Pole","Alquiler",IF(LEFT(I19,7)="1 Clase","Clase suelta","Paquete"))) -> Paquete | K19: Promo 2x1 | L19: 1 | M19: 240000 | N19: =IF(M19="","",L19*M19) -> 240000 | O19: 0.5 | P19: Nequi | R19: =IF(C19="","",IF(COUNTIF($C$2:C19,C19)=1,"Nueva","Recurrente")) -> Nueva | S19: =IF(OR(C19="",J19<>"Paquete"),"",COUNTIFS($C$2:C19,C19,$J$2:J19,"Paquete")) -> 1
A20: I-020 | B20: 46283 | C20: Juliana Bossa | D20: =IF($C20="","",IFERROR(IF(INDEX('🎓 Alumnas'!$C$2:$C$1000,MATCH($C20,'🎓 Alumnas'!$B$2:$B$1000,0))="","",INDEX('🎓 Alumnas'!$C$2:$C$1000,MATCH($C20,'🎓 Alumnas'!$B$2:$B$1000,0))),"")) -> 3185937737 | E20: =IF($C20="","",IFERROR(IF(INDEX('🎓 Alumnas'!$D$2:$D$1000,MATCH($C20,'🎓 Alumnas'!$B$2:$B$1000,0))="","",INDEX('🎓 Alumnas'!$D$2:$D$1000,MATCH($C20,'🎓 Alumnas'!$B$2:$B$1000,0))),"")) | F20: =IF($C20="","",IFERROR(IF(INDEX('🎓 Alumnas'!$E$2:$E$1000,MATCH($C20,'🎓 Alumnas'!$B$2:$B$1000,0))="","",INDEX('🎓 Alumnas'!$E$2:$E$1000,MATCH($C20,'🎓 Alumnas'!$B$2:$B$1000,0))),"")) | G20: =IF($C20="","",IFERROR(IF(INDEX('🎓 Alumnas'!$F$2:$F$1000,MATCH($C20,'🎓 Alumnas'!$B$2:$B$1000,0))="","",INDEX('🎓 Alumnas'!$F$2:$F$1000,MATCH($C20,'🎓 Alumnas'!$B$2:$B$1000,0))),"")) | H20: =IF(G20="","",DATEDIF(G20,TODAY(),"Y")) | I20: 1 Pole: Alquiler $22000 | J20: =IF(I20="","",IF(LEFT(I20,6)="1 Pole","Alquiler",IF(LEFT(I20,7)="1 Clase","Clase suelta","Paquete"))) -> Alquiler | L20: 1 | M20: 22000 | N20: =IF(M20="","",L20*M20) -> 22000 | O20: 1 | P20: Transferencia Bancaria | R20: =IF(C20="","",IF(COUNTIF($C$2:C20,C20)=1,"Nueva","Recurrente")) -> Recurrente | S20: =IF(OR(C20="",J20<>"Paquete"),"",COUNTIFS($C$2:C20,C20,$J$2:J20,"Paquete"))
A21: I-021 | B21: 46283 | C21: Mary Aurora Osorio Alvarez | D21: =IF($C21="","",IFERROR(IF(INDEX('🎓 Alumnas'!$C$2:$C$1000,MATCH($C21,'🎓 Alumnas'!$B$2:$B$1000,0))="","",INDEX('🎓 Alumnas'!$C$2:$C$1000,MATCH($C21,'🎓 Alumnas'!$B$2:$B$1000,0))),"")) -> 3186650375 | E21: =IF($C21="","",IFERROR(IF(INDEX('🎓 Alumnas'!$D$2:$D$1000,MATCH($C21,'🎓 Alumnas'!$B$2:$B$1000,0))="","",INDEX('🎓 Alumnas'!$D$2:$D$1000,MATCH($C21,'🎓 Alumnas'!$B$2:$B$1000,0))),"")) | F21: =IF($C21="","",IFERROR(IF(INDEX('🎓 Alumnas'!$E$2:$E$1000,MATCH($C21,'🎓 Alumnas'!$B$2:$B$1000,0))="","",INDEX('🎓 Alumnas'!$E$2:$E$1000,MATCH($C21,'🎓 Alumnas'!$B$2:$B$1000,0))),"")) | G21: =IF($C21="","",IFERROR(IF(INDEX('🎓 Alumnas'!$F$2:$F$1000,MATCH($C21,'🎓 Alumnas'!$B$2:$B$1000,0))="","",INDEX('🎓 Alumnas'!$F$2:$F$1000,MATCH($C21,'🎓 Alumnas'!$B$2:$B$1000,0))),"")) | H21: =IF(G21="","",DATEDIF(G21,TODAY(),"Y")) | I21: 1 Clase: Individual $50000 | J21: =IF(I21="","",IF(LEFT(I21,6)="1 Pole","Alquiler",IF(LEFT(I21,7)="1 Clase","Clase suelta","Paquete"))) -> Clase suelta | L21: 1 | M21: 50000 | N21: =IF(M21="","",L21*M21) -> 50000 | O21: 1 | P21: Nequi | R21: =IF(C21="","",IF(COUNTIF($C$2:C21,C21)=1,"Nueva","Recurrente")) -> Nueva | S21: =IF(OR(C21="",J21<>"Paquete"),"",COUNTIFS($C$2:C21,C21,$J$2:J21,"Paquete"))
